Workbook

Sheet CI_
A1: ??? | B1: K_USUARIO_ACCION | C1: [K_SISTEMA] | D1: [D_sistema_tag] | E1: [D_sistema_tag_menu] | F1: [S_Sistema_tag] | G1: [O_Sistema_tag] | H1: [C_Sistema_tag] | I1: [R_Sistema_tag] | J1: [L_Sistema_tag] | K1: [K_GRUPO_TAG] | L1: [L_ARCHIVO_TAG] | M1: [K_IMAGEN_ARCHIVO] | O1: EXECUTE [dbo].[ | P1: PG_CI_SISTEMA_TAG | Q1: ] | R1: =CONCATENATE($O$1,$P$1,$Q$1, B3, ", ", ) -> EXECUTE [dbo].[PG_CI_SISTEMA_TAG] 139,
B2: - | C2: - | D2: - | F2: - | G2: - | H2: - | J2: - | K2: - | O2: ="-- ==========================================================" -> -- ==========================================================
B3: 139 | C3: 0 | D3: (NO-SISTEMA) | E3: ( NO-SISTEMA ) | F3: ( N/S ) | G3: =C3 -> 0 | H3: #0 // (NO-SISTEMA) | J3: 1 | K3: 0 | L3: 0 | M3: 1 | O3: =CONCATENATE(CI_!$R$1,C3,", '",D3,"', '",E3,"', '",F3,"' , ",G3," , '",H3,"' , '",I3,"', ",J3,",",K3,",",L3,",",M3) -> EXECUTE [dbo].[PG_CI_SISTEMA_TAG] 139, 0, '(NO-SISTEMA)', '( NO-SISTEMA )', '( N/S )' , 0 , '#0 // (NO-SISTEMA)' , '', 1,0,0,1
B4: 139 | C4: 1 | D4: prod_rpt | E4: PRODUCTION REPORT | F4: #001 | G4: 1 | J4: 1 | K4: 70 | L4: 0 | M4: 1 | O4: =CONCATENATE(CI_!$R$1,C4,", '",D4,"', '",E4,"', '",F4,"' , ",G4," , '",H4,"' , '",I4,"', ",J4,",",K4,",",L4,",",M4) -> EXECUTE [dbo].[PG_CI_SISTEMA_TAG] 139, 1, 'prod_rpt', 'PRODUCTION REPORT', '#001' , 1 , '' , '', 1,70,0,1
B5: 139 | C5: 2 | D5: SupScreen | E5: SUPERVISORS | F5: #002 | G5: 2 | J5: 1 | K5: 70 | L5: 0 | M5: 30 | O5: =CONCATENATE(CI_!$R$1,C5,", '",D5,"', '",E5,"', '",F5,"' , ",G5," , '",H5,"' , '",I5,"', ",J5,",",K5,",",L5,",",M5) -> EXECUTE [dbo].[PG_CI_SISTEMA_TAG] 139, 2, 'SupScreen', 'SUPERVISORS', '#002' , 2 , '' , '', 1,70,0,30
B6: 139 | C6: 3 | D6: frmMain2 | E6: PRODUCTION | F6: #003 | G6: 3 | J6: 1 | K6: 70 | L6: 0 | M6: 26 | O6: =CONCATENATE(CI_!$R$1,C6,", '",D6,"', '",E6,"', '",F6,"' , ",G6," , '",H6,"' , '",I6,"', ",J6,",",K6,",",L6,",",M6) -> EXECUTE [dbo].[PG_CI_SISTEMA_TAG] 139, 3, 'frmMain2', 'PRODUCTION', '#003' , 3 , '' , '', 1,70,0,26
B7: 139 | C7: 4 | D7: rej | E7: REJECTS | F7: #004 | G7: 4 | J7: 1 | K7: 70 | L7: 0 | M7: 24 | O7: =CONCATENATE(CI_!$R$1,C7,", '",D7,"', '",E7,"', '",F7,"' , ",G7," , '",H7,"' , '",I7,"', ",J7,",",K7,",",L7,",",M7) -> EXECUTE [dbo].[PG_CI_SISTEMA_TAG] 139, 4, 'rej', 'REJECTS', '#004' , 4 , '' , '', 1,70,0,24
B8: 139 | C8: 5 | D8: Planning | E8: PLANNING SCREEN | F8: #005 | G8: 5 | J8: 1 | K8: 60 | L8: 0 | M8: 21 | O8: =CONCATENATE(CI_!$R$1,C8,", '",D8,"', '",E8,"', '",F8,"' , ",G8," , '",H8,"' , '",I8,"', ",J8,",",K8,",",L8,",",M8) -> EXECUTE [dbo].[PG_CI_SISTEMA_TAG] 139, 5, 'Planning', 'PLANNING SCREEN', '#005' , 5 , '' , '', 1,60,0,21
B9: 139 | C9: 6 | D9: Transferencias | E9: TRANSACTIONS | F9: #006 | G9: 6 | J9: 1 | K9: 60 | L9: 0 | M9: 19 | O9: =CONCATENATE(CI_!$R$1,C9,", '",D9,"', '",E9,"', '",F9,"' , ",G9," , '",H9,"' , '",I9,"', ",J9,",",K9,",",L9,",",M9) -> EXECUTE [dbo].[PG_CI_SISTEMA_TAG] 139, 6, 'Transferencias', 'TRANSACTIONS', '#006' , 6 , '' , '', 1,60,0,19
B10: 139 | C10: 7 | D10: sc_pieles2 | E10: HIDES SCANNER | F10: #007 | G10: 7 | J10: 0 | K10: 60 | L10: 0 | M10: 7 | O10: =CONCATENATE(CI_!$R$1,C10,", '",D10,"', '",E10,"', '",F10,"' , ",G10," , '",H10,"' , '",I10,"', ",J10,",",K10,",",L10,",",M10) -> EXECUTE [dbo].[PG_CI_SISTEMA_TAG] 139, 7, 'sc_pieles2', 'HIDES SCANNER', '#007' , 7 , '' , '', 0,60,0,7
B11: 139 | C11: 8 | D11: labels | E11: LABELS | F11: #008 | G11: 8 | J11: 1 | K11: 60 | L11: 0 | M11: 35 | O11: =CONCATENATE(CI_!$R$1,C11,", '",D11,"', '",E11,"', '",F11,"' , ",G11," , '",H11,"' , '",I11,"', ",J11,",",K11,",",L11,",",M11) -> EXECUTE [dbo].[PG_CI_SISTEMA_TAG] 139, 8, 'labels', 'LABELS', '#008' , 8 , '' , '', 1,60,0,35
B12: 139 | C12: 9 | D12: etiqueta_piel | E12: HIDE LABELS | F12: #009 | G12: 9 | J12: 1 | K12: 60 | L12: 0 | M12: 34 | O12: =CONCATENATE(CI_!$R$1,C12,", '",D12,"', '",E12,"', '",F12,"' , ",G12," , '",H12,"' , '",I12,"', ",J12,",",K12,",",L12,",",M12) -> EXECUTE [dbo].[PG_CI_SISTEMA_TAG] 139, 9, 'etiqueta_piel', 'HIDE LABELS', '#009' , 9 , '' , '', 1,60,0,34
B13: 139 | C13: 10 | D13: Packing | E13: PACKING SLIP | F13: #010 | G13: 10 | J13: 1 | K13: 20 | L13: 0 | M13: 14 | O13: =CONCATENATE(CI_!$R$1,C13,", '",D13,"', '",E13,"', '",F13,"' , ",G13," , '",H13,"' , '",I13,"', ",J13,",",K13,",",L13,",",M13) -> EXECUTE [dbo].[PG_CI_SISTEMA_TAG] 139, 10, 'Packing', 'PACKING SLIP', '#010' , 10 , '' , '', 1,20,0,14
B14: 139 | C14: 11 | D14: FO_TRANSFER_SCREEN | E14: TRANSFER MCT TO MFP | F14: #011 | G14: 11 | J14: 1 | K14: 20 | L14: 0 | M14: 20 | O14: =CONCATENATE(CI_!$R$1,C14,", '",D14,"', '",E14,"', '",F14,"' , ",G14," , '",H14,"' , '",I14,"', ",J14,",",K14,",",L14,",",M14) -> EXECUTE [dbo].[PG_CI_SISTEMA_TAG] 139, 11, 'FO_TRANSFER_SCREEN', 'TRANSFER MCT TO MFP', '#011' , 11 , '' , '', 1,20,0,20
B15: 139 | C15: 12 | D15: InventMFP | E15: MFP INVENTORY | F15: #012 | G15: 12 | J15: 1 | K15: 20 | L15: 0 | M15: 12 | O15: =CONCATENATE(CI_!$R$1,C15,", '",D15,"', '",E15,"', '",F15,"' , ",G15," , '",H15,"' , '",I15,"', ",J15,",",K15,",",L15,",",M15) -> EXECUTE [dbo].[PG_CI_SISTEMA_TAG] 139, 12, 'InventMFP', 'MFP INVENTORY', '#012' , 12 , '' , '', 1,20,0,12
... B23: 139 | C23: 20 | D23: frmRange | E23: STOCK STATUS | F23: #020 | G23: 20 | J23: 1 | K23: 40 | L23: 0 | M23: 4 | O23: =CONCATENATE(CI_!$R$1,C23,", '",D23,"', '",E23,"', '",F23,"' , ",G23," , '",H23,"' , '",I23,"', ",J23,",",K23,",",L23,",",M23) -> EXECUTE [dbo].[PG_CI_SISTEMA_TAG] 139, 20, 'frmRange', 'STOCK STATUS', '#020' , 20 , '' , '', 1,40,0,4
B24: 139 | C24: 21 | D24: EXCEL_PRODUCTION_REPORT | E24: EXCEL PRODUCTION REPORT | F24: #021 | G24: 21 | I24: \\10.1.1.5\documents\PEARL\Reportes\Excel Production Report.xlsm | J24: 1 | K24: 70 | L24: 1 | M24: 32 | O24: =CONCATENATE(CI_!$R$1,C24,", '",D24,"', '",E24,"', '",F24,"' , ",G24," , '",H24,"' , '",I24,"', ",J24,",",K24,",",L24,",",M24) -> EXECUTE [dbo].[PG_CI_SISTEMA_TAG] 139, 21, 'EXCEL_PRODUCTION_REPORT', 'EXCEL PRODUCTION REPORT', '#021' , 21 , '' , '\\10.1.1.5\documents\PEARL\Reportes\Excel Production Report.xlsm', 1,70,1,32
B25: 139 | C25: 22 | D25: BELL_CURVE | E25: BELL CURVE | F25: #022 | G25: 22 | I25: \\10.1.1.5\documents\PEARL\Reportes\Bell_Curve_Report.xls | J25: 1 | K25: 40 | L25: 1 | M25: 14 | O25: =CONCATENATE(CI_!$R$1,C25,", '",D25,"', '",E25,"', '",F25,"' , ",G25," , '",H25,"' , '",I25,"', ",J25,",",K25,",",L25,",",M25) -> EXECUTE [dbo].[PG_CI_SISTEMA_TAG] 139, 22, 'BELL_CURVE', 'BELL CURVE', '#022' , 22 , '' , '\\10.1.1.5\documents\PEARL\Reportes\Bell_Curve_Report.xls', 1,40,1,14
B26: 139 | C26: 23 | D26: TransactionsReport | E26: TRANSACTION REPORT | F26: #023 | G26: 23 | J26: 1 | K26: 60 | L26: 0 | M26: 7 | O26: =CONCATENATE(CI_!$R$1,C26,", '",D26,"', '",E26,"', '",F26,"' , ",G26," , '",H26,"' , '",I26,"', ",J26,",",K26,",",L26,",",M26) -> EXECUTE [dbo].[PG_CI_SISTEMA_TAG] 139, 23, 'TransactionsReport', 'TRANSACTION REPORT', '#023' , 23 , '' , '', 1,60,0,7
B27: 139 | C27: 24 | D27: CERTIFICATION_REPORT | E27: CERTIFICATION REPORT | F27: #024 | G27: 24 | J27: 1 | K27: 10 | L27: 0 | M27: 21 | O27: =CONCATENATE(CI_!$R$1,C27,", '",D27,"', '",E27,"', '",F27,"' , ",G27," , '",H27,"' , '",I27,"', ",J27,",",K27,",",L27,",",M27) -> EXECUTE [dbo].[PG_CI_SISTEMA_TAG] 139, 24, 'CERTIFICATION_REPORT', 'CERTIFICATION REPORT', '#024' , 24 , '' , '', 1,10,0,21
B28: 139 | C28: 25 | D28: FoliosInv | E28: FOLIOS INVENTORY | F28: #025 | G28: 25 | J28: 1 | K28: 60 | L28: 0 | M28: 6 | N28: 20 | O28: =CONCATENATE(CI_!$R$1,C28,", '",D28,"', '",E28,"', '",F28,"' , ",G28," , '",H28,"' , '",I28,"', ",J28,",",K28,",",L28,",",M28) -> EXECUTE [dbo].[PG_CI_SISTEMA_TAG] 139, 25, 'FoliosInv', 'FOLIOS INVENTORY', '#025' , 25 , '' , '', 1,60,0,6
B29: 139 | C29: 26 | D29: QUALITY_REJECTS | E29: QUALITY REJECTS | F29: #026 | G29: 26 | J29: 1 | K29: 10 | L29: 0 | M29: 24 | O29: =CONCATENATE(CI_!$R$1,C29,", '",D29,"', '",E29,"', '",F29,"' , ",G29," , '",H29,"' , '",I29,"', ",J29,",",K29,",",L29,",",M29) -> EXECUTE [dbo].[PG_CI_SISTEMA_TAG] 139, 26, 'QUALITY_REJECTS', 'QUALITY REJECTS', '#026' , 26 , '' , '', 1,10,0,24
B30: 139 | C30: 27 | D30: PackingSlipMexico | E30: PACKING MACOLA | F30: #027 | G30: 27 | J30: 1 | K30: 20 | L30: 0 | M30: 10 | O30: =CONCATENATE(CI_!$R$1,C30,", '",D30,"', '",E30,"', '",F30,"' , ",G30," , '",H30,"' , '",I30,"', ",J30,",",K30,",",L30,",",M30) -> EXECUTE [dbo].[PG_CI_SISTEMA_TAG] 139, 27, 'PackingSlipMexico', 'PACKING MACOLA', '#027' , 27 , '' , '', 1,20,0,10
B31: 139 | C31: 28 | D31: Tags | E31: TAGS | F31: #028 | G31: 28 | J31: 1 | K31: 30 | L31: 0 | M31: 36 | O31: =CONCATENATE(CI_!$R$1,C31,", '",D31,"', '",E31,"', '",F31,"' , ",G31," , '",H31,"' , '",I31,"', ",J31,",",K31,",",L31,",",M31) -> EXECUTE [dbo].[PG_CI_SISTEMA_TAG] 139, 28, 'Tags', 'TAGS', '#028' , 28 , '' , '', 1,30,0,36
B32: 139 | C32: 29 | D32: SalesByCust | E32: SALES BY CUST | F32: #029 | G32: 29 | J32: 1 | K32: 30 | L32: 0 | M32: 38 | O32: =CONCATENATE(CI_!$R$1,C32,", '",D32,"', '",E32,"', '",F32,"' , ",G32," , '",H32,"' , '",I32,"', ",J32,",",K32,",",L32,",",M32) -> EXECUTE [dbo].[PG_CI_SISTEMA_TAG] 139, 29, 'SalesByCust', 'SALES BY CUST', '#029' , 29 , '' , '', 1,30,0,38
B33: 139 | C33: 30 | D33: PolizaNomina | E33: POLIZA DE NOMINA | F33: #030 | G33: 30 | J33: 1 | K33: 30 | L33: 0 | M33: 25 | O33: =CONCATENATE(CI_!$R$1,C33,", '",D33,"', '",E33,"', '",F33,"' , ",G33," , '",H33,"' , '",I33,"', ",J33,",",K33,",",L33,",",M33) -> EXECUTE [dbo].[PG_CI_SISTEMA_TAG] 139, 30, 'PolizaNomina', 'POLIZA DE NOMINA', '#030' , 30 , '' , '', 1,30,0,25
B34: 139 | C34: 31 | D34: HistoryByPackL | E34: HISTORY BY JOB NO | F34: #031 | G34: 31 | J34: 1 | K34: 60 | L34: 0 | M34: 15 | O34: =CONCATENATE(CI_!$R$1,C34,", '",D34,"', '",E34,"', '",F34,"' , ",G34," , '",H34,"' , '",I34,"', ",J34,",",K34,",",L34,",",M34) -> EXECUTE [dbo].[PG_CI_SISTEMA_TAG] 139, 31, 'HistoryByPackL', 'HISTORY BY JOB NO', '#031' , 31 , '' , '', 1,60,0,15
B35: 139 | C35: 32 | D35: PatternsDatabase | E35: PATTERN LABELS | F35: #032 | G35: 32 | J35: 1 | K35: 90 | L35: 0 | M35: 39 | O35: =CONCATENATE(CI_!$R$1,C35,", '",D35,"', '",E35,"', '",F35,"' , ",G35," , '",H35,"' , '",I35,"', ",J35,",",K35,",",L35,",",M35) -> EXECUTE [dbo].[PG_CI_SISTEMA_TAG] 139, 32, 'PatternsDatabase', 'PATTERN LABELS', '#032' , 32 , '' , '', 1,90,0,39
B36: 139 | C36: 33 | D36: Leather planning | E36: Leather planning | F36: #033 | G36: 33 | J36: 0 | K36: 40 | L36: 0 | M36: 1 | O36: =CONCATENATE(CI_!$R$1,C36,", '",D36,"', '",E36,"', '",F36,"' , ",G36," , '",H36,"' , '",I36,"', ",J36,",",K36,",",L36,",",M36) -> EXECUTE [dbo].[PG_CI_SISTEMA_TAG] 139, 33, 'Leather planning ', 'Leather planning ', '#033' , 33 , '' , '', 0,40,0,1
B37: 139 | C37: 34 | D37: Cum_Report | E37: CUMULATIVE REPORT | F37: #034 | G37: 34 | J37: 1 | K37: 60 | L37: 0 | M37: 7 | O37: =CONCATENATE(CI_!$R$1,C37,", '",D37,"', '",E37,"', '",F37,"' , ",G37," , '",H37,"' , '",I37,"', ",J37,",",K37,",",L37,",",M37) -> EXECUTE [dbo].[PG_CI_SISTEMA_TAG] 139, 34, 'Cum_Report', 'CUMULATIVE REPORT', '#034' , 34 , '' , '', 1,60,0,7
B38: 139 | C38: 35 | D38: INCOMING_INSPECTION | E38: INCOMING INSPECTION | F38: #035 | G38: 35 | J38: 1 | K38: 10 | L38: 0 | M38: 27 | O38: =CONCATENATE(CI_!$R$1,C38,", '",D38,"', '",E38,"', '",F38,"' , ",G38," , '",H38,"' , '",I38,"', ",J38,",",K38,",",L38,",",M38) -> EXECUTE [dbo].[PG_CI_SISTEMA_TAG] 139, 35, 'INCOMING_INSPECTION', 'INCOMING INSPECTION', '#035' , 35 , '' , '', 1,10,0,27
B39: 139 | C39: 36 | D39: STATUS_DE_ORDENES | E39: STATUS DE ORDENES | F39: #036 | G39: 36 | J39: 1 | K39: 10 | L39: 0 | M39: 17 | O39: =CONCATENATE(CI_!$R$1,C39,", '",D39,"', '",E39,"', '",F39,"' , ",G39," , '",H39,"' , '",I39,"', ",J39,",",K39,",",L39,",",M39) -> EXECUTE [dbo].[PG_CI_SISTEMA_TAG] 139, 36, 'STATUS_DE_ORDENES', 'STATUS DE ORDENES', '#036' , 36 , '' , '', 1,10,0,17
B40: 139 | C40: 37 | D40: UpdateTarget | E40: UPDATE TARGETS | F40: #037 | G40: 37 | J40: 1 | K40: 40 | L40: 0 | M40: 38 | O40: =CONCATENATE(CI_!$R$1,C40,", '",D40,"', '",E40,"', '",F40,"' , ",G40," , '",H40,"' , '",I40,"', ",J40,",",K40,",",L40,",",M40) -> EXECUTE [dbo].[PG_CI_SISTEMA_TAG] 139, 37, 'UpdateTarget', 'UPDATE TARGETS', '#037' , 37 , '' , '', 1,40,0,38
B41: 139 | C41: 38 | D41: colors | E41: COLORS MANT | F41: #038 | G41: 38 | J41: 1 | K41: 50 | L41: 0 | M41: 28 | N41: 40 | O41: =CONCATENATE(CI_!$R$1,C41,", '",D41,"', '",E41,"', '",F41,"' , ",G41," , '",H41,"' , '",I41,"', ",J41,",",K41,",",L41,",",M41) -> EXECUTE [dbo].[PG_CI_SISTEMA_TAG] 139, 38, 'colors', 'COLORS MANT', '#038' , 38 , '' , '', 1,50,0,28
B42: 139 | C42: 39 | D42: LOT_COMP | E42: LOT COMP | F42: #039 | G42: 39 | J42: 1 | K42: 10 | L42: 0 | M42: 14 | O42: =CONCATENATE(CI_!$R$1,C42,", '",D42,"', '",E42,"', '",F42,"' , ",G42," , '",H42,"' , '",I42,"', ",J42,",",K42,",",L42,",",M42) -> EXECUTE [dbo].[PG_CI_SISTEMA_TAG] 139, 39, 'LOT_COMP', 'LOT COMP', '#039' , 39 , '' , '', 1,10,0,14
B43: 139 | C43: 40 | D43: INV IT | E43: INV IT | F43: #040 | G43: 40 | J43: 0 | K43: 90 | L43: 0 | M43: 1 | O43: =CONCATENATE(CI_!$R$1,C43,", '",D43,"', '",E43,"', '",F43,"' , ",G43," , '",H43,"' , '",I43,"', ",J43,",",K43,",",L43,",",M43) -> EXECUTE [dbo].[PG_CI_SISTEMA_TAG] 139, 40, 'INV IT', 'INV IT', '#040' , 40 , '' , '', 0,90,0,1
B44: 139 | C44: 41 | D44: Eng_main | E44: ENGINEERING SCREEN | F44: #041 | G44: 41 | J44: 1 | K44: 50 | L44: 0 | M44: 22 | O44: =CONCATENATE(CI_!$R$1,C44,", '",D44,"', '",E44,"', '",F44,"' , ",G44," , '",H44,"' , '",I44,"', ",J44,",",K44,",",L44,",",M44) -> EXECUTE [dbo].[PG_CI_SISTEMA_TAG] 139, 41, 'Eng_main', 'ENGINEERING SCREEN', '#041' , 41 , '' , '', 1,50,0,22
B45: 139 | C45: 42 | D45: ProdCat | E45: PROD CATEGORY | F45: #042 | G45: 42 | J45: 1 | K45: 50 | L45: 0 | M45: 10 | O45: =CONCATENATE(CI_!$R$1,C45,", '",D45,"', '",E45,"', '",F45,"' , ",G45," , '",H45,"' , '",I45,"', ",J45,",",K45,",",L45,",",M45) -> EXECUTE [dbo].[PG_CI_SISTEMA_TAG] 139, 42, 'ProdCat', 'PROD CATEGORY', '#042' , 42 , '' , '', 1,50,0,10
B46: 139 | C46: 43 | D46: ItemMaster | E46: ITEM MASTER | F46: #043 | G46: 43 | J46: 1 | K46: 50 | L46: 0 | M46: 30 | O46: =CONCATENATE(CI_!$R$1,C46,", '",D46,"', '",E46,"', '",F46,"' , ",G46," , '",H46,"' , '",I46,"', ",J46,",",K46,",",L46,",",M46) -> EXECUTE [dbo].[PG_CI_SISTEMA_TAG] 139, 43, 'ItemMaster', 'ITEM MASTER', '#043' , 43 , '' , '', 1,50,0,30
B47: 139 | C47: 44 | D47: KitMaster | E47: KIT MASTER | F47: #044 | G47: 44 | J47: 1 | K47: 50 | L47: 0 | M47: 17 | O47: =CONCATENATE(CI_!$R$1,C47,", '",D47,"', '",E47,"', '",F47,"' , ",G47," , '",H47,"' , '",I47,"', ",J47,",",K47,",",L47,",",M47) -> EXECUTE [dbo].[PG_CI_SISTEMA_TAG] 139, 44, 'KitMaster', 'KIT MASTER', '#044' , 44 , '' , '', 1,50,0,17
...

Sheet Sheet1
C3: GRUPO_TAG | E3: SISTEMA_TAG
B4: 10 | C4: calidad | E4: production report | F4: 70
B5: 20 | C5: final | E5: supervisors | F5: 70
B6: 30 | C6: finanzas | E6: production | F6: 70
B7: 40 | C7: general | E7: rejects | F7: 70
B8: 50 | C8: ingenieria | E8: planning screen | F8: 60
B9: 60 | C9: materiales | E9: transactions | F9: 60
B10: 70 | C10: produccion | E10: hides scanner | F10: 60
B11: 80 | C11: recursos humanos | E11: packing slip | F11: 20
B12: 90 | C12: sistemas | E12: transfer mct to mfp | F12: 20
E13: mfp inventory | F13: 20
E14: labels | F14: 60
E15: hide labels | F15: 60
E16: ppms | F16: 10
E17: load release | F17: 60
E18: edi weekly rpt | F18: 60
E19: daily inventory | F19: 20
E20: hides allocation | F20: 40
E21: human resources | F21: 80
E22: stock status | F22: 40
E23: excel production report | F23: 70
E24: bell curve | F24: 40
... E70: cotizaciones | F70: 50

Sheet Sheet4
A2: codigo | B2: nombre | C2: apellido | D2: usuario | E2: contrasena | F2: correo | G2: tipo | H2: tema | J2: K_USUARIO_PEARL | K2: D_USUARIO_PEARL | L2: NOMBRE | M2: APELLIDO_PATERNO | N2: APELLIDO_MATERNO | O2: CORREO_USUARIO_PEARL | P2: PASSWORD_USUARIO_PEARL | Q2: TEMA_USUARIO_PEARL | R2: K_USUARIO_DEPARTAMENTO | S2: K_USUARIO_TIPO | T2: K_EMPLEADO_PEARL | U2: K_USUARIO_ALTA | V2: F_ALTA | W2: K_USUARIO_CAMBIO | X2: F_CAMBIO | Y2: L_BORRADO | Z2: K_USUARIO_BAJA | AA2: F_BAJA
A3: 41 | B3: Rafael | C3: Fierro | D3: rafaelf | E3: killer | F3: rafaelf@pearlleather.com.mx | G3: A1 | H3: Red Planet.isl | J3: 41 | K3: RAFAELF | L3: RAFAEL | M3: FIERRO | N3: MASCORRO | O3: RAFAELF@PEARLLEATHER.COM.MX | P3: killer | Q3: RED PLANET.ISL | R3: 7 | S3: 30 | T3: 6142 | U3: 139 | V3: 44004.427 | W3: 139 | X3: 44004.427 | Y3: 0 | Z3: NULL | AA3: NULL
A4: 42 | B4: Omar | C4: Decena | D4: omard | E4: 12340 | F4: omard@pearlleather.com.mx | G4: Q1 | H4: Red Planet.isl | J4: 42 | K4: OMARD | L4: OMAR ALBERTO | M4: DECENA | N4: MARTINEZ | O4: OMARD@PEARLLEATHER.COM.MX | P4: 12340 | Q4: RED PLANET.ISL | R4: 12 | S4: 20 | T4: 181 | U4: 139 | V4: 44004.427 | W4: 139 | X4: 44004.427 | Y4: 0 | Z4: NULL | AA4: NULL
A5: 43 | B5: Jorge | C5: Holguin | D5: jorgeh | E5: jorgeh | F5: jorgeh@pearlleather.com.mx | G5: U2 | H5: Flat Nature.isl | J5: 43 | K5: JORGEH | L5: JORGE FELIPE | M5: HOLGUIN | N5: NAVA | O5: JORGEH@PEARLLEATHER.COM.MX | P5: jorgeh | Q5: FLAT NATURE.ISL | R5: 9 | S5: 50 | T5: 52 | U5: 139 | V5: 44004.427 | W5: 139 | X5: 44004.427 | Y5: 0 | Z5: NULL | AA5: NULL
A6: 44 | B6: Guillermo | C6: Mata | D6: guillermom | E6: nicole | F6: guillermom@pearlleather.com.mx | G6: U1 | H6: Flat Nature.isl | J6: 44 | K6: GUILLERMOM | L6: GUILLERMO ALFONSO | M6: MATA | N6: RODRIGUEZ | O6: GUILLERMOM@PEARLLEATHER.COM.MX | P6: nicole | Q6: FLAT NATURE.ISL | R6: 6 | S6: 40 | T6: 22 | U6: 139 | V6: 44004.427 | W6: 139 | X6: 44004.427 | Y6: 0 | Z6: NULL | AA6: NULL
A7: 45 | B7: Pedro | C7: Vargas | D7: pedrov | E7: Saver10* | F7: pedrov@pearlleather.com.mx | G7: U1 | H7: Red Planet.isl | J7: 45 | K7: PEDROV | L7: PEDRO | M7: VARGAS | N7: FRAGOSO | O7: PEDROV@PEARLLEATHER.COM.MX | P7: Saver10* | Q7: RED PLANET.ISL | R7: 3 | S7: 40 | T7: 999 | U7: 139 | V7: 44004.427 | W7: 139 | X7: 44004.427 | Y7: 0 | Z7: NULL | AA7: NULL
A8: 47 | B8: Miguel | C8: Carrasco | D8: miguelc | E8: Dalica9905 | F8: miguelc@pearlleather.com.mx | G8: Q1 | H8: Flat Nature.isl | J8: 47 | K8: MIGUELC | L8: JESUS MIGUEL | M8: CARRASCO | N8: ORTIZ | O8: MIGUELC@PEARLLEATHER.COM.MX | P8: Dalica9905 | Q8: FLAT NATURE.ISL | R8: 4 | S8: 20 | T8: 1299 | U8: 139 | V8: 44004.427 | W8: 139 | X8: 44004.427 | Y8: 0 | Z8: NULL | AA8: NULL
A9: 48 | B9: Ivan | C9: Decena | D9: ivand | E9: 5623 | F9: ivand@pearlleather.com.mx | G9: U | H9: IG Style.isl | J9: 48 | K9: IVAND | L9: IVAN ANDRES | M9: DECENA | N9: MARTINEZ | O9: IVAND@PEARLLEATHER.COM.MX | P9: 5623 | Q9: IG STYLE.ISL | R9: 4 | S9: 30 | T9: 2091 | U9: 139 | V9: 44004.427 | W9: 139 | X9: 44004.427 | Y9: 0 | Z9: NULL | AA9: NULL
A10: 49 | B10: Oscar | C10: Torres | D10: oscart | E10: 7890 | F10: oscart@pearlleather.com.mx | G10: U | H10: Natilus.isl | J10: 49 | K10: OSCART | L10: OSCAR OMAR | M10: TORRES | N10: BUGARIN | O10: OSCART@PEARLLEATHER.COM.MX | P10: 7890 | Q10: NATILUS.ISL | R10: 2 | S10: 30 | T10: 10901 | U10: 139 | V10: 44004.427 | W10: 139 | X10: 44004.427 | Y10: 0 | Z10: NULL | AA10: NULL
A11: 51 | B11: Recibo1 | D11: recibo1 | E11: 12345 | F11: pedroa@pearlleather.com.mx | G11: U | H11: IG Style.isl | J11: 51 | K11: RECIBO1 | O11: PEDROA@PEARLLEATHER.COM.MX | P11: 12345 | Q11: IG STYLE.ISL | R11: 0 | S11: 30 | T11: 0 | U11: 139 | V11: 44004.427 | W11: 139 | X11: 44004.427 | Y11: 0 | Z11: NULL | AA11: NULL
A12: 52 | B12: Recibo2 | D12: recibo2 | E12: 12340 | F12: pedroa@pearlleather.com.mx | G12: U | H12: The Blues.isl | J12: 52 | K12: RECIBO2 | O12: PEDROA@PEARLLEATHER.COM.MX | P12: 12340 | Q12: THE BLUES.ISL | R12: 0 | S12: 30 | T12: 0 | U12: 139 | V12: 44004.427 | W12: 139 | X12: 44004.427 | Y12: 0 | Z12: NULL | AA12: NULL
A13: 54 | B13: Gilberto | C13: Vazquez | D13: gilbertov | E13: Alexander1 | F13: gilbertov@pearlleather.com.mx | G13: U1 | H13: Red Planet.isl | J13: 54 | K13: GILBERTOV | L13: GILBERTO | M13: VAZQUEZ | N13: RAMIREZ | O13: GILBERTOV@PEARLLEATHER.COM.MX | P13: Alexander1 | Q13: RED PLANET.ISL | R13: 1 | S13: 40 | T13: 6898 | U13: 139 | V13: 44004.427 | W13: 139 | X13: 44004.427 | Y13: 0 | Z13: NULL | AA13: NULL
A14: 56 | B14: Manuel | C14: Garcia | D14: manuelg | E14: Mangar83 | F14: manuelg@pearlleather.com.mx | G14: U2 | H14: Flat Nature.isl | J14: 56 | K14: MANUELG | L14: MANUEL MAURILIO | M14: GARCIA | N14: ORTIZ | O14: MANUELG@PEARLLEATHER.COM.MX | P14: Mangar83 | Q14: FLAT NATURE.ISL | R14: 3 | S14: 50 | T14: 4475 | U14: 139 | V14: 44004.427 | W14: 139 | X14: 44004.427 | Y14: 0 | Z14: NULL | AA14: NULL
A15: 57 | B15: Fabiola | C15: Gerardo | D15: fabiolag | E15: fabiola | F15: fabiolag@pearlleather.com.mx | G15: U | H15: Flat Nature.isl | J15: 57 | K15: FABIOLAG | L15: ALEXIS FABIOLA | M15: GERARDO | N15: AREVALO | O15: FABIOLAG@PEARLLEATHER.COM.MX | P15: fabiola | Q15: FLAT NATURE.ISL | R15: 8 | S15: 30 | T15: 7658 | U15: 139 | V15: 44004.427 | W15: 139 | X15: 44004.427 | Y15: 0 | Z15: NULL | AA15: NULL
A16: 58 | B16: Diana | C16: Salas | D16: dianas | E16: 1604 | F16: @pearlleather.com.mx | G16: U | H16: Natilus.isl | J16: 58 | K16: DIANAS | L16: DIANA JANNET | M16: SALAS | N16: TOVAR | P16: 1604 | Q16: FLAT NATURE.ISL | R16: 3 | S16: 30 | T16: 10151 | U16: 139 | V16: 44004.427 | W16: 139 | X16: 44004.427 | Y16: 0 | Z16: NULL | AA16: NULL
A17: 59 | B17: Alejandro | C17: Perez | D17: alejandrop | E17: alex | F17: embarques1@pearlleather.com.mx | G17: U | H17: Flat Nature.isl | J17: 59 | K17: ALEJANDROP | L17: ALEJANDRO | M17: PEREZ | N17: REYES | O17: EMBARQUES1@PEARLLEATHER.COM.MX | P17: alex | Q17: FLAT NATURE.ISL | R17: 3 | S17: 30 | T17: 6176 | U17: 139 | V17: 44004.427 | W17: 139 | X17: 44004.427 | Y17: 0 | Z17: NULL | AA17: NULL
A18: 60 | B18: Adriana | C18: De la Ree | D18: adrianad | E18: adriana | F18: adrianad@pearlleather.com.mx | G18: U | H18: Flat Nature.isl | J18: 60 | K18: ADRIANAD | L18: ADRIANA | M18: DE LA REE | N18: DOMINGUEZ | O18: ADRIANAD@PEARLLEATHER.COM.MX | P18: adriana | Q18: FLAT NATURE.ISL | R18: 8 | S18: 30 | T18: 67 | U18: 139 | V18: 44004.427 | W18: 139 | X18: 44004.427 | Y18: 0 | Z18: NULL | AA18: NULL
A19: 62 | B19: Patricia | C19: Chavez | D19: patriciac | E19: mebi1625 | F19: patriciac@pearlleather.com.mx | G19: U | H19: Flat Nature.isl | J19: 62 | K19: PATRICIAC | L19: MARTHA PATRICIA | M19: CHAVEZ | N19: VARGAS | O19: PATRICIAC@PEARLLEATHER.COM.MX | P19: mebi1625 | Q19: FLAT NATURE.ISL | R19: 1 | S19: 30 | T19: 7945 | U19: 139 | V19: 44004.427 | W19: 139 | X19: 44004.427 | Y19: 0 | Z19: NULL | AA19: NULL
A20: 63 | B20: Luis | C20: Perez | D20: luisp | E20: luis | F20: luisp@pearlleather.com.mx | G20: U1 | H20: IG Style.isl | J20: 63 | K20: LUISP | O20: LUISP@PEARLLEATHER.COM.MX | P20: luis | Q20: IG STYLE.ISL | R20: 0 | S20: 40 | T20: 0 | U20: 139 | V20: 44004.427 | W20: 139 | X20: 44004.427 | Y20: 1 | Z20: NULL | AA20: NULL
A21: 64 | B21: Leonor | C21: Hernandez | D21: leonorh | E21: 12340 | F21: leonorh@pearlleather.com.mx | G21: P1 | H21: Red Planet.isl | J21: 64 | K21: LEONORH | L21: LEONOR ADRIANA | M21: HERNANDEZ | N21: MARTINEZ | O21: LEONORH@PEARLLEATHER.COM.MX | P21: 12340 | Q21: RED PLANET.ISL | R21: 2 | S21: 30 | T21: 7549 | U21: 139 | V21: 44004.427 | W21: 139 | X21: 44004.427 | Y21: 0 | Z21: NULL | AA21: NULL
A22: 66 | B22: Karen | C22: Espinoza | D22: karene | E22: 200816 | F22: recibo@pearlleather.com.mx | G22: U | H22: Red Planet.isl | J22: 66 | K22: KARENE | L22: KAREN SELENE | M22: ESPINOZA | N22: RANGEL | O22: RECIBO@PEARLLEATHER.COM.MX | P22: 200816 | Q22: RED PLANET.ISL | R22: 3 | S22: 30 | T22: 10382 | U22: 139 | V22: 44004.427 | W22: 139 | X22: 44004.427 | Y22: 0 | Z22: NULL | AA22: NULL
A23: 67 | B23: Gaspar | C23: Hinojos | D23: gasparh | E23: 12345 | F23: gasparh@pearlleather.com.mx | G23: P1 | H23: The Blues.isl | J23: 67 | K23: GASPARH | L23: GASPAR | M23: HINOJOS | N23: HERNANDEZ | O23: GASPARH@PEARLLEATHER.COM.MX | P23: 12345 | Q23: THE BLUES.ISL | R23: 2 | S23: 30 | T23: 5628 | U23: 139 | V23: 44004.427 | W23: 139 | X23: 44004.427 | Y23: 0 | Z23: NULL | AA23: NULL
A24: 68 | B24: Armida | C24: Hernandez | D24: armidah | E24: 2878 | F24: armidah@pearlleather.com.mx | G24: P1 | H24: Flat Nature.isl | J24: 68 | K24: ARMIDAH | L24: ARMIDA | M24: HERNANDEZ | N24: RIVERA | O24: ARMIDAH@PEARLLEATHER.COM.MX | P24: 2878 | Q24: FLAT NATURE.ISL | R24: 2 | S24: 30 | T24: 7041 | U24: 139 | V24: 44004.427 | W24: 139 | X24: 44004.427 | Y24: 0 | Z24: NULL | AA24: NULL
A25: 69 | B25: Mary | C25: Sosa | D25: marias | E25: 12345 | F25: marias@pearlleather.com.mx | G25: U | H25: Flat Nature.isl | J25: 69 | K25: MARIAS | L25: MARIA DE LA LUZ | M25: SOSA | N25: SEDANO | O25: MARIAS@PEARLLEATHER.COM.MX | P25: 12345 | Q25: FLAT NATURE.ISL | R25: 8 | S25: 30 | T25: 4158 | U25: 139 | V25: 44004.427 | W25: 139 | X25: 44004.427 | Y25: 0 | Z25: NULL | AA25: NULL
A26: 70 | B26: Fernando | C26: Garcia | D26: fernandog | E26: ferny | F26: fernandog@pearlleather.com.mx | G26: U1 | H26: Red Planet.isl | J26: 70 | K26: FERNANDOG | L26: FERNANDO | M26: GARCIA | N26: ANTE | O26: FERNANDOG@PEARLLEATHER.COM.MX | P26: ferny | Q26: RED PLANET.ISL | R26: 3 | S26: 40 | T26: 8464 | U26: 139 | V26: 44004.427 | W26: 139 | X26: 44004.427 | Y26: 0 | Z26: NULL | AA26: NULL
A27: 71 | B27: Navid | C27: Rachman | D27: navidr | E27: kgi01! | F27: navid@rachmantech.com | G27: U | H27: Flat Nature.isl | J27: 71 | K27: NAVIDR | L27: NAVID | M27: RACHMAN | O27: NAVID@RACHMANTECH.COM | P27: kgi01! | Q27: FLAT NATURE.ISL | R27: 0 | S27: 30 | T27: -1 | U27: 139 | V27: 44004.427 | W27: 139 | X27: 44004.427 | Y27: 0 | Z27: NULL | AA27: NULL
A28: 72 | B28: Roxana | C28: Lara | D28: roxanal | E28: 123789 | F28: @pearlleather.com.mx | G28: U1 | H28: The Blues.isl | J28: 72 | K28: ROXANAL | L28: ROXANA EDITH | M28: LARA | N28: AMADOR | P28: 123789 | Q28: THE BLUES.ISL | R28: 4 | S28: 40 | T28: 11879 | U28: 139 | V28: 44004.427 | W28: 139 | X28: 44004.427 | Y28: 0 | Z28: NULL | AA28: NULL
A29: 73 | B29: Yamilex | C29: Quezada | D29: yamilexq | E29: 1234 | F29: yamilexq@pearlleather.com.mx | G29: P1 | H29: Flat Nature.isl | J29: 73 | K29: YAMILEXQ | O29: YAMILEXQ@PEARLLEATHER.COM.MX | P29: 1234 | Q29: FLAT NATURE.ISL | R29: 0 | S29: 30 | T29: 0 | U29: 139 | V29: 44004.427 | W29: 139 | X29: 44004.427 | Y29: 1 | Z29: NULL | AA29: NULL
A30: 75 | B30: Karen | C30: Anaya | D30: karena | E30: 102 | F30: karena@pearlleather.com.mx | G30: U | H30: Noir Moderne.isl | J30: 75 | K30: KARENA | L30: KAREN MICHELLE | M30: APOLONIO | N30: SOTO | O30: KARENA@PEARLLEATHER.COM.MX | P30: 102 | Q30: NOIR MODERNE.ISL | R30: 4 | S30: 30 | T30: 12769 | U30: 139 | V30: 44004.427 | W30: 139 | X30: 44004.427 | Y30: 0 | Z30: NULL | AA30: NULL
A31: 77 | B31: Genaro | C31: Hernandez | D31: genaroh | E31: 12345 | F31: embarques1@pearlleather.com.mx | G31: U | H31: Flat Nature.isl | J31: 77 | K31: GENAROH | L31: GENARO | M31: HERNANDEZ | N31: SANCHEZ | O31: EMBARQUES1@PEARLLEATHER.COM.MX | P31: 12345 | Q31: FLAT NATURE.ISL | R31: 3 | S31: 30 | T31: 4880 | U31: 139 | V31: 44004.427 | W31: 139 | X31: 44004.427 | Y31: 0 | Z31: NULL | AA31: NULL
A32: 82 | B32: Dana | C32: Conde | D32: danac | E32: 2697 | F32: certi@pearlleather.com.mx | G32: U | H32: Flat Nature.isl | J32: 82 | K32: DANAC | L32: DANA YARETH | M32: CONDE | N32: MENDEZ | O32: CERTI@PEARLLEATHER.COM.MX | P32: 2697 | Q32: FLAT NATURE.ISL | R32: 4 | S32: 30 | T32: 10054 | U32: 139 | V32: 44004.427 | W32: 139 | X32: 44004.427 | Y32: 0 | Z32: NULL | AA32: NULL
A33: 83 | B33: Mariana | C33: Castro | D33: marianac | E33: 1986 | F33: certi@pearlleather.com.mx | G33: U | H33: Red Planet.isl | J33: 83 | K33: MARIANAC | O33: CERTI@PEARLLEATHER.COM.MX | P33: 1986 | Q33: RED PLANET.ISL | R33: 0 | S33: 30 | T33: 0 | U33: 139 | V33: 44004.427 | W33: 139 | X33: 44004.427 | Y33: 1 | Z33: NULL | AA33: NULL
A34: 86 | B34: Jorge | C34: Olegario | D34: jorgeo | E34: calidad.30 | F34: jolegario@pearlleather.com.mx | G34: U | H34: Flat Nature.isl | J34: 86 | K34: JORGEO | L34: JORGE OLEGARIO | M34: MIGUEL | N34: LOPEZ | O34: JOLEGARIO@PEARLLEATHER.COM.MX | P34: calidad.30 | Q34: FLAT NATURE.ISL | R34: 4 | S34: 30 | T34: 3589 | U34: 139 | V34: 44004.427 | W34: 139 | X34: 44004.427 | Y34: 0 | Z34: NULL | AA34: NULL
A35: 87 | B35: Diana | C35: Navarrete | D35: dianan | E35: Facturas1 | F35: recibo@pearlleather.com.mx | G35: U1 | H35: Red Planet.isl | J35: 87 | K35: DIANAN | L35: DIANA CECILIA | M35: NAVARRETE | N35: MARTINEZ | O35: DIANAN@PEARLLEATHER.COM.MX | P35: Facturas1 | Q35: RED PLANET.ISL | R35: 3 | S35: 40 | T35: 10221 | U35: 139 | V35: 44004.427 | W35: 139 | X35: 44004.427 | Y35: 0 | Z35: NULL | AA35: NULL
A36: 88 | B36: sistemas | D36: sistemas | E36: m@ster++ | F36: sistemas@pearlleather.com.mx | G36: A1 | H36: Red Planet.isl | J36: 88 | K36: SISTEMAS | O36: SISTEMAS@PEARLLEATHER.COM.MX | P36: m@ster++ | Q36: RED PLANET.ISL | R36: 0 | S36: 30 | T36: 0 | U36: 139 | V36: 44004.427 | W36: 139 | X36: 44004.427 | Y36: 0 | Z36: NULL | AA36: NULL
A37: 89 | B37: Viviana | C37: Chavez | D37: vivianac | E37: 123450 | F37: vivianc@pearlleather.com.mx | G37: Q1 | H37: Flat Nature.isl | J37: 89 | K37: VIVIANAC | L37: VIVIANA ANGELICA | M37: CHAVEZ | N37: ZUNIGA | O37: VIVIANC@PEARLLEATHER.COM.MX | P37: 123450 | Q37: FLAT NATURE.ISL | R37: 4 | S37: 30 | T37: 8242 | U37: 139 | V37: 44004.427 | W37: 139 | X37: 44004.427 | Y37: 0 | Z37: NULL | AA37: NULL
A38: 90 | B38: Tania | C38: Cruz | D38: taniac | E38: 1726 | F38: recibo@pearlleather.com.mx | G38: U | H38: Flat Nature.isl | J38: 90 | K38: TANIAC | L38: TANIA ELIZABETH | M38: CRUZ | N38: HERNANDEZ | O38: RECIBO@PEARLLEATHER.COM.MX | P38: 1726 | Q38: BLACK STYLE.ISL | R38: 3 | S38: 30 | T38: 10209 | U38: 139 | V38: 44004.427 | W38: 139 | X38: 44004.427 | Y38: 0 | Z38: NULL | AA38: NULL
A39: 92 | B39: Jose | C39: Sanchez | D39: joses | E39: jose48320031 | F39: joses@pearlleather.com.mx | G39: U | H39: IG Style.isl | J39: 92 | K39: JOSES | L39: JOSE LUIS | M39: SANCHEZ | N39: CORDOVA | O39: JOSES@PEARLLEATHER.COM.MX | P39: jose48320031 | Q39: IG STYLE.ISL | R39: 2 | S39: 30 | T39: 13253 | U39: 139 | V39: 44004.427 | W39: 139 | X39: 44004.427 | Y39: 0 | Z39: NULL | AA39: NULL
A40: 93 | B40: Maria | C40: Romo | D40: mariar | E40: 12345 | F40: mariar@pearlleather.com.mx | G40: P1 | H40: Natilus.isl | J40: 93 | K40: MARIAR | O40: MARIAR@PEARLLEATHER.COM.MX | P40: 12345 | Q40: NATILUS.ISL | R40: 0 | S40: 30 | T40: 0 | U40: 139 | V40: 44004.427 | W40: 139 | X40: 44004.427 | Y40: 1 | Z40: NULL | AA40: NULL
A41: 94 | B41: Francisco | C41: Morales | D41: franciscom | E41: cuarris987 | F41: @pearlleather.com.mx | G41: U | H41: IG Style.isl | J41: 94 | K41: FRANCISCOM | L41: FRANCISCO GABRIEL | M41: MORALES | N41: LOPEZ | P41: cuarris987 | Q41: IG STYLE.ISL | R41: 2 | S41: 30 | T41: 13189 | U41: 139 | V41: 44004.427 | W41: 139 | X41: 44004.427 | Y41: 0 | Z41: NULL | AA41: NULL
...

Sheet MENUSS
B3: opt_cd | C3: descripcion | D3: grupo | F3: d_grupo_tag | G3: K_SISTEMA_TAG | H3: D_SISTEMA_TAG | I3: D_SISTEMA_TAG_MENU | J3: S_SISTEMA_TAG | K3: O_SISTEMA_TAG | L3: C_SISTEMA_TAG | M3: R_SISTEMA_TAG | N3: L_SISTEMA_TAG | O3: k_grupo_tag | P3: L_ARCHIVO_TAG | Q3: K_IMAGEN_SISTEMA_TAG
B4: 1 | C4: Production report | D4: Produccion | F4: PRODUCCION | G4: 1 | H4: prod_rpt | I4: PRODUCTION REPORT | J4: #001 | K4: 1 | N4: 1 | O4: 70 | P4: 0 | Q4: 1
B5: 2 | C5: Supervisors | D5: Produccion | F5: PRODUCCION | G5: 2 | H5: SupScreen | I5: SUPERVISORS | J5: #002 | K5: 2 | N5: 1 | O5: 70 | P5: 0 | Q5: 30
B6: 3 | C6: Production | D6: Produccion | F6: PRODUCCION | G6: 3 | H6: frmMain2 | I6: PRODUCTION | J6: #003 | K6: 3 | N6: 1 | O6: 70 | P6: 0 | Q6: 26
B7: 4 | C7: Rejects | D7: Produccion | F7: PRODUCCION | G7: 4 | H7: rej | I7: REJECTS | J7: #004 | K7: 4 | N7: 1 | O7: 70 | P7: 0 | Q7: 24
B8: 5 | C8: Planning screen | D8: Materiales | F8: MATERIALES | G8: 5 | H8: Planning | I8: PLANNING SCREEN | J8: #005 | K8: 5 | N8: 1 | O8: 60 | P8: 0 | Q8: 21
B9: 6 | C9: Transactions | D9: Materiales | F9: MATERIALES | G9: 6 | H9: Transferencias | I9: TRANSACTIONS | J9: #006 | K9: 6 | N9: 1 | O9: 60 | P9: 0 | Q9: 19
B10: 7 | C10: Hides scanner | D10: Materiales | F10: MATERIALES | G10: 7 | H10: sc_pieles2 | I10: HIDES SCANNER | J10: #007 | K10: 7 | N10: 0 | O10: 60 | P10: 0 | Q10: 7
B11: 8 | C11: Labels | D11: Materiales | F11: FINAL | G11: 8 | H11: Packing | I11: PACKING SLIP | J11: #008 | K11: 8 | N11: 1 | O11: 20 | P11: 0 | Q11: 14
B12: 9 | C12: Hide labels | D12: Materiales | F12: FINAL | G12: 9 | H12: FO_TRANSFER_SCREEN | I12: TRANSFER MCT TO MFP | J12: #009 | K12: 9 | N12: 1 | O12: 20 | P12: 0 | Q12: 20
B13: 10 | C13: Packing slip | D13: Final | F13: FINAL | G13: 10 | H13: InventMFP | I13: MFP INVENTORY | J13: #010 | K13: 10 | N13: 1 | O13: 20 | P13: 0 | Q13: 12
B14: 11 | C14: Transfer MCT to MFP | D14: Final | F14: MATERIALES | G14: 11 | H14: labels | I14: LABELS | J14: #011 | K14: 11 | N14: 1 | O14: 60 | P14: 0 | Q14: 35
B15: 12 | C15: MFP inventory | D15: Final | F15: MATERIALES | G15: 12 | H15: etiqueta_piel | I15: HIDE LABELS | J15: #012 | K15: 12 | N15: 1 | O15: 60 | P15: 0 | Q15: 34
... B19: 16 | C19: Daily inventory | D19: Final | F19: FINAL | G19: 16 | H19: InvD | I19: DAILY INVENTORY | J19: #016 | K19: 16 | N19: 1 | O19: 20 | P19: 0 | Q19: 25
B20: 17 | C20: 2D Bar code | D20: NY
B21: 18 | C21: Hides allocation | D21: General | F21: GENERAL | G21: 17 | H21: HidesAllocation | I21: HIDES ALLOCATION | J21: #017 | K21: 17 | N21: 1 | O21: 40 | P21: 0 | Q21: 2
B22: 19 | C22: Human resources | D22: Recursos Humanos | F22: RECURSOS_HUMANOS | G22: 18 | H22: personal | I22: HUMAN RESOURCES | J22: #018 | K22: 18 | N22: 1 | O22: 80 | P22: 0 | Q22: 4
B23: 20 | C23: Stock status | D23: General | F23: GENERAL | G23: 19 | H23: frmRange | I23: STOCK STATUS | J23: #019 | K23: 19 | N23: 1 | O23: 40 | P23: 0 | Q23: 4
B24: 21 | C24: Excel production report | D24: Produccion | F24: PRODUCCION | G24: 20 | H24: EXCEL_PRODUCTION_REPORT | I24: EXCEL PRODUCTION REPORT | J24: #020 | K24: 20 | M24: \\10.1.1.5\documents\PEARL\Reportes\Excel Production Report.xlsm | N24: 1 | O24: 70 | P24: 1 | Q24: 32
B25: 22 | C25: Bell curve | D25: General | F25: GENERAL | G25: 21 | H25: BELL_CURVE | I25: BELL CURVE | J25: #021 | K25: 21 | M25: \\10.1.1.5\documents\PEARL\Reportes\Bell_Curve_Report.xls | N25: 1 | O25: 40 | P25: 1 | Q25: 14
B26: 23 | C26: Transaction report | D26: Materiales | F26: MATERIALES | G26: 22 | H26: TransactionsReport | I26: TRANSACTION REPORT | J26: #022 | K26: 22 | N26: 1 | O26: 60 | P26: 0 | Q26: 7
B27: 24 | C27: Certification report | D27: Calidad | F27: CALIDAD | G27: 23 | H27: CERTIFICATION_REPORT | I27: CERTIFICATION REPORT | J27: #023 | K27: 23 | N27: 1 | O27: 10 | P27: 0 | Q27: 21
B28: 25 | C28: Folios inventory | D28: Final | F28: MATERIALES | G28: 24 | H28: FoliosInv | I28: FOLIOS INVENTORY | J28: #024 | K28: 24 | N28: 1 | O28: 60 | P28: 0 | Q28: 6
B29: 26 | C29: Quality rejects | D29: Calidad | F29: CALIDAD | G29: 25 | H29: QUALITY_REJECTS | I29: QUALITY REJECTS | J29: #025 | K29: 25 | N29: 1 | O29: 10 | P29: 0 | Q29: 24
B30: 27 | C30: Packing macola | D30: Final | F30: FINAL | G30: 26 | H30: PackingSlipMexico | I30: PACKING MACOLA | J30: #026 | K30: 26 | N30: 1 | O30: 20 | P30: 0 | Q30: 10
B31: 28 | C31: Tags | D31: Finanzas | F31: FINANZAS | G31: 27 | H31: Tags | I31: TAGS | J31: #027 | K31: 27 | N31: 1 | O31: 30 | P31: 0 | Q31: 36
B32: 29 | C32: Sales By Cust | D32: Finanzas | F32: FINANZAS | G32: 28 | H32: SalesByCust | I32: SALES BY CUST | J32: #028 | K32: 28 | N32: 1 | O32: 30 | P32: 0 | Q32: 38
B33: 30 | C33: Poliza de nomina | D33: Finanzas | F33: FINANZAS | G33: 29 | H33: PolizaNomina | I33: POLIZA DE NOMINA | J33: #029 | K33: 29 | N33: 1 | O33: 30 | P33: 0 | Q33: 25
B34: 31 | C34: History By Job No | D34: Materiales | F34: MATERIALES | G34: 30 | H34: HistoryByPackL | I34: HISTORY BY JOB NO | J34: #030 | K34: 30 | N34: 1 | O34: 60 | P34: 0 | Q34: 15
B35: 32 | C35: Pattern Labels | D35: Sistemas | F35: SISTEMAS | G35: 31 | H35: PatternsDatabase | I35: PATTERN LABELS | J35: #031 | K35: 31 | N35: 1 | O35: 90 | P35: 0 | Q35: 39
B36: 33 | C36: Leather planning | D36: General
B37: 34 | C37: Cumulative Report | D37: Materiales | F37: MATERIALES | G37: 32 | H37: Cum_Report | I37: CUMULATIVE REPORT | J37: #032 | K37: 32 | N37: 1 | O37: 60 | P37: 0 | Q37: 7
B38: 35 | C38: Incoming Inspection | D38: Calidad | F38: CALIDAD | G38: 33 | H38: INCOMING_INSPECTION | I38: INCOMING INSPECTION | J38: #033 | K38: 33 | N38: 1 | O38: 10 | P38: 0 | Q38: 27
B39: 36 | C39: Status de Ordenes | D39: Calidad | F39: CALIDAD | G39: 34 | H39: STATUS_DE_ORDENES | I39: STATUS DE ORDENES | J39: #034 | K39: 34 | N39: 1 | O39: 10 | P39: 0 | Q39: 17
B40: 37 | C40: Update Targets | D40: General | F40: INGENIERIA | G40: 35 | H40: colors | I40: COLORS MANT | J40: #035 | K40: 35 | N40: 1 | O40: 50 | P40: 0 | Q40: 28
B41: 38 | C41: Colors Mant | D41: General | F41: GENERAL | G41: 36 | H41: UpdateTarget | I41: UPDATE TARGETS | J41: #036 | K41: 36 | N41: 1 | O41: 40 | P41: 0 | Q41: 38
B42: 39 | C42: Lot Comp | D42: Calidad | F42: CALIDAD | G42: 37 | H42: LOT_COMP | I42: LOT COMP | J42: #037 | K42: 37 | N42: 1 | O42: 10 | P42: 0 | Q42: 14
B43: 40 | C43: Inv IT | D43: Sistemas
B44: 41 | C44: Engineering Screen | D44: General | F44: INGENIERIA | G44: 38 | H44: Eng_main | I44: ENGINEERING SCREEN | J44: #038 | K44: 38 | N44: 1 | O44: 50 | P44: 0 | Q44: 22
B45: 42 | C45: Prod Category | D45: General | F45: INGENIERIA | G45: 39 | H45: ProdCat | I45: PROD CATEGORY | J45: #039 | K45: 39 | N45: 1 | O45: 50 | P45: 0 | Q45: 10
...
