Workbook

Sheet CI_
A1: ??? | B1: K_USUARIO_ACCION | C1: [K_USUARIO_PEARL] | D1: [D_USUARIO_PEARL] | E1: [PASSWORD_USUARIO_PEARL] | F1: [CORREO_USUARIO_PEARL] | G1: [K_USUARIO_DEPTO] | H1: [K_USUARIO_TIPO] | I1: [TEMA_USUARIO_PEARL] | J1: [K_EMPLEADO_PEARL] | K1: [C_USUARIO_PEARL] | L1: [L_USUARIO_PEARL] | M1: [L_BORRADO] | O1: EXECUTE [dbo].[ | P1: PG_CI_USUARIO_PEARL | Q1: ] | R1: =CONCATENATE($O$1,$P$1,$Q$1, B3, ", ", ) -> EXECUTE [dbo].[PG_CI_USUARIO_PEARL] 139,
B2: - | C2: - | D2: - | E2: - | F2: - | G2: - | H2: - | L2: - | M2: - | O2: ="-- ==========================================================" -> -- ==========================================================
B3: 139 | C3: 41 | D3: RAFAELF | E3: killer | F3: RAFAELF@PEARLLEATHER.COM.MX | G3: 7 | H3: 30 | I3: RED PLANET.ISL | J3: 6142 | L3: 1 | M3: 0 | O3: =CONCATENATE(CI_!$R$1,C3,", '",D3,"', '",E3,"' , '",F3,"' , ",G3,",",H3,",'",I3,"',",J3,",'",K3,"',",L3,",",M3) -> EXECUTE [dbo].[PG_CI_USUARIO_PEARL] 139, 41, 'RAFAELF', 'killer' , 'RAFAELF@PEARLLEATHER.COM.MX' , 7,30,'RED PLANET.ISL',6142,'',1,0
B4: 139 | C4: 42 | D4: OMARD | E4: 12340 | F4: OMARD@PEARLLEATHER.COM.MX | G4: 12 | H4: 20 | I4: RED PLANET.ISL | J4: 181 | L4: 1 | M4: 0 | O4: =CONCATENATE(CI_!$R$1,C4,", '",D4,"', '",E4,"' , '",F4,"' , ",G4,",",H4,",'",I4,"',",J4,",'",K4,"',",L4,",",M4) -> EXECUTE [dbo].[PG_CI_USUARIO_PEARL] 139, 42, 'OMARD', '12340' , 'OMARD@PEARLLEATHER.COM.MX' , 12,20,'RED PLANET.ISL',181,'',1,0
B5: 139 | C5: 43 | D5: JORGEH | E5: jorgeh | F5: JORGEH@PEARLLEATHER.COM.MX | G5: 9 | H5: 50 | I5: FLAT NATURE.ISL | J5: 52 | L5: 1 | M5: 0 | O5: =CONCATENATE(CI_!$R$1,C5,", '",D5,"', '",E5,"' , '",F5,"' , ",G5,",",H5,",'",I5,"',",J5,",'",K5,"',",L5,",",M5) -> EXECUTE [dbo].[PG_CI_USUARIO_PEARL] 139, 43, 'JORGEH', 'jorgeh' , 'JORGEH@PEARLLEATHER.COM.MX' , 9,50,'FLAT NATURE.ISL',52,'',1,0
B6: 139 | C6: 44 | D6: GUILLERMOM | E6: nicole | F6: GUILLERMOM@PEARLLEATHER.COM.MX | G6: 6 | H6: 40 | I6: FLAT NATURE.ISL | J6: 22 | L6: 1 | M6: 0 | O6: =CONCATENATE(CI_!$R$1,C6,", '",D6,"', '",E6,"' , '",F6,"' , ",G6,",",H6,",'",I6,"',",J6,",'",K6,"',",L6,",",M6) -> EXECUTE [dbo].[PG_CI_USUARIO_PEARL] 139, 44, 'GUILLERMOM', 'nicole' , 'GUILLERMOM@PEARLLEATHER.COM.MX' , 6,40,'FLAT NATURE.ISL',22,'',1,0
B7: 139 | C7: 45 | D7: PEDROV | E7: Saver10* | F7: PEDROV@PEARLLEATHER.COM.MX | G7: 3 | H7: 40 | I7: RED PLANET.ISL | J7: 999 | L7: 1 | M7: 0 | O7: =CONCATENATE(CI_!$R$1,C7,", '",D7,"', '",E7,"' , '",F7,"' , ",G7,",",H7,",'",I7,"',",J7,",'",K7,"',",L7,",",M7) -> EXECUTE [dbo].[PG_CI_USUARIO_PEARL] 139, 45, 'PEDROV', 'Saver10*' , 'PEDROV@PEARLLEATHER.COM.MX' , 3,40,'RED PLANET.ISL',999,'',1,0
B8: 139 | C8: 47 | D8: MIGUELC | E8: Dalica9905 | F8: MIGUELC@PEARLLEATHER.COM.MX | G8: 4 | H8: 20 | I8: FLAT NATURE.ISL | J8: 1299 | L8: 1 | M8: 0 | O8: =CONCATENATE(CI_!$R$1,C8,", '",D8,"', '",E8,"' , '",F8,"' , ",G8,",",H8,",'",I8,"',",J8,",'",K8,"',",L8,",",M8) -> EXECUTE [dbo].[PG_CI_USUARIO_PEARL] 139, 47, 'MIGUELC', 'Dalica9905' , 'MIGUELC@PEARLLEATHER.COM.MX' , 4,20,'FLAT NATURE.ISL',1299,'',1,0
B9: 139 | C9: 48 | D9: IVAND | E9: 5623 | F9: IVAND@PEARLLEATHER.COM.MX | G9: 4 | H9: 30 | I9: IG STYLE.ISL | J9: 2091 | L9: 1 | M9: 0 | O9: =CONCATENATE(CI_!$R$1,C9,", '",D9,"', '",E9,"' , '",F9,"' , ",G9,",",H9,",'",I9,"',",J9,",'",K9,"',",L9,",",M9) -> EXECUTE [dbo].[PG_CI_USUARIO_PEARL] 139, 48, 'IVAND', '5623' , 'IVAND@PEARLLEATHER.COM.MX' , 4,30,'IG STYLE.ISL',2091,'',1,0
B10: 139 | C10: 49 | D10: OSCART | E10: 7890 | F10: OSCART@PEARLLEATHER.COM.MX | G10: 2 | H10: 30 | I10: NATILUS.ISL | J10: 10901 | L10: 1 | M10: 0 | O10: =CONCATENATE(CI_!$R$1,C10,", '",D10,"', '",E10,"' , '",F10,"' , ",G10,",",H10,",'",I10,"',",J10,",'",K10,"',",L10,",",M10) -> EXECUTE [dbo].[PG_CI_USUARIO_PEARL] 139, 49, 'OSCART', '7890' , 'OSCART@PEARLLEATHER.COM.MX' , 2,30,'NATILUS.ISL',10901,'',1,0
B11: 139 | C11: 51 | D11: RECIBO1 | E11: 12345 | F11: PEDROA@PEARLLEATHER.COM.MX | H11: 30 | I11: IG STYLE.ISL | J11: 0 | K11: recibo | L11: 1 | M11: 0 | O11: =CONCATENATE(CI_!$R$1,C11,", '",D11,"', '",E11,"' , '",F11,"' , ",G11,",",H11,",'",I11,"',",J11,",'",K11,"',",L11,",",M11) -> EXECUTE [dbo].[PG_CI_USUARIO_PEARL] 139, 51, 'RECIBO1', '12345' , 'PEDROA@PEARLLEATHER.COM.MX' , ,30,'IG STYLE.ISL',0,'recibo',1,0
B12: 139 | C12: 52 | D12: RECIBO2 | E12: 12340 | F12: PEDROA@PEARLLEATHER.COM.MX | H12: 30 | I12: THE BLUES.ISL | J12: 0 | K12: recibo | L12: 1 | M12: 0 | O12: =CONCATENATE(CI_!$R$1,C12,", '",D12,"', '",E12,"' , '",F12,"' , ",G12,",",H12,",'",I12,"',",J12,",'",K12,"',",L12,",",M12) -> EXECUTE [dbo].[PG_CI_USUARIO_PEARL] 139, 52, 'RECIBO2', '12340' , 'PEDROA@PEARLLEATHER.COM.MX' , ,30,'THE BLUES.ISL',0,'recibo',1,0
B13: 139 | C13: 54 | D13: GILBERTOV | E13: Alexander1 | F13: GILBERTOV@PEARLLEATHER.COM.MX | G13: 1 | H13: 40 | I13: RED PLANET.ISL | J13: 6898 | L13: 1 | M13: 0 | O13: =CONCATENATE(CI_!$R$1,C13,", '",D13,"', '",E13,"' , '",F13,"' , ",G13,",",H13,",'",I13,"',",J13,",'",K13,"',",L13,",",M13) -> EXECUTE [dbo].[PG_CI_USUARIO_PEARL] 139, 54, 'GILBERTOV', 'Alexander1' , 'GILBERTOV@PEARLLEATHER.COM.MX' , 1,40,'RED PLANET.ISL',6898,'',1,0
B14: 139 | C14: 56 | D14: MANUELG | E14: Mangar83 | F14: MANUELG@PEARLLEATHER.COM.MX | G14: 3 | H14: 50 | I14: FLAT NATURE.ISL | J14: 4475 | L14: 1 | M14: 0 | O14: =CONCATENATE(CI_!$R$1,C14,", '",D14,"', '",E14,"' , '",F14,"' , ",G14,",",H14,",'",I14,"',",J14,",'",K14,"',",L14,",",M14) -> EXECUTE [dbo].[PG_CI_USUARIO_PEARL] 139, 56, 'MANUELG', 'Mangar83' , 'MANUELG@PEARLLEATHER.COM.MX' , 3,50,'FLAT NATURE.ISL',4475,'',1,0
B15: 139 | C15: 57 | D15: FABIOLAG | E15: fabiola | F15: FABIOLAG@PEARLLEATHER.COM.MX | G15: 8 | H15: 30 | I15: FLAT NATURE.ISL | J15: 7658 | L15: 1 | M15: 0 | O15: =CONCATENATE(CI_!$R$1,C15,", '",D15,"', '",E15,"' , '",F15,"' , ",G15,",",H15,",'",I15,"',",J15,",'",K15,"',",L15,",",M15) -> EXECUTE [dbo].[PG_CI_USUARIO_PEARL] 139, 57, 'FABIOLAG', 'fabiola' , 'FABIOLAG@PEARLLEATHER.COM.MX' , 8,30,'FLAT NATURE.ISL',7658,'',1,0
B16: 139 | C16: 58 | D16: DIANAS | E16: 1604 | F16: @PEARLLEATHER.COM.MX | G16: 3 | H16: 30 | I16: FLAT NATURE.ISL | J16: 10151 | L16: 1 | M16: 0 | O16: =CONCATENATE(CI_!$R$1,C16,", '",D16,"', '",E16,"' , '",F16,"' , ",G16,",",H16,",'",I16,"',",J16,",'",K16,"',",L16,",",M16) -> EXECUTE [dbo].[PG_CI_USUARIO_PEARL] 139, 58, 'DIANAS', '1604' , '@PEARLLEATHER.COM.MX' , 3,30,'FLAT NATURE.ISL',10151,'',1,0
B17: 139 | C17: 59 | D17: ALEJANDROP | E17: alex | F17: EMBARQUES1@PEARLLEATHER.COM.MX | G17: 3 | H17: 30 | I17: FLAT NATURE.ISL | J17: 6176 | L17: 1 | M17: 0 | O17: =CONCATENATE(CI_!$R$1,C17,", '",D17,"', '",E17,"' , '",F17,"' , ",G17,",",H17,",'",I17,"',",J17,",'",K17,"',",L17,",",M17) -> EXECUTE [dbo].[PG_CI_USUARIO_PEARL] 139, 59, 'ALEJANDROP', 'alex' , 'EMBARQUES1@PEARLLEATHER.COM.MX' , 3,30,'FLAT NATURE.ISL',6176,'',1,0
B18: 139 | C18: 60 | D18: ADRIANAD | E18: adriana | F18: ADRIANAD@PEARLLEATHER.COM.MX | G18: 8 | H18: 30 | I18: FLAT NATURE.ISL | J18: 67 | L18: 1 | M18: 0 | O18: =CONCATENATE(CI_!$R$1,C18,", '",D18,"', '",E18,"' , '",F18,"' , ",G18,",",H18,",'",I18,"',",J18,",'",K18,"',",L18,",",M18) -> EXECUTE [dbo].[PG_CI_USUARIO_PEARL] 139, 60, 'ADRIANAD', 'adriana' , 'ADRIANAD@PEARLLEATHER.COM.MX' , 8,30,'FLAT NATURE.ISL',67,'',1,0
B19: 139 | C19: 62 | D19: PATRICIAC | E19: mebi1625 | F19: PATRICIAC@PEARLLEATHER.COM.MX | G19: 1 | H19: 30 | I19: FLAT NATURE.ISL | J19: 7945 | L19: 1 | M19: 0 | O19: =CONCATENATE(CI_!$R$1,C19,", '",D19,"', '",E19,"' , '",F19,"' , ",G19,",",H19,",'",I19,"',",J19,",'",K19,"',",L19,",",M19) -> EXECUTE [dbo].[PG_CI_USUARIO_PEARL] 139, 62, 'PATRICIAC', 'mebi1625' , 'PATRICIAC@PEARLLEATHER.COM.MX' , 1,30,'FLAT NATURE.ISL',7945,'',1,0
B20: 139 | C20: 63 | D20: LUISP | E20: luis | F20: LUISP@PEARLLEATHER.COM.MX | H20: 40 | I20: IG STYLE.ISL | J20: 0 | K20: luis perez | L20: 1 | M20: 1 | O20: =CONCATENATE(CI_!$R$1,C20,", '",D20,"', '",E20,"' , '",F20,"' , ",G20,",",H20,",'",I20,"',",J20,",'",K20,"',",L20,",",M20) -> EXECUTE [dbo].[PG_CI_USUARIO_PEARL] 139, 63, 'LUISP', 'luis' , 'LUISP@PEARLLEATHER.COM.MX' , ,40,'IG STYLE.ISL',0,'luis perez',1,1
B21: 139 | C21: 64 | D21: LEONORH | E21: 12340 | F21: LEONORH@PEARLLEATHER.COM.MX | G21: 2 | H21: 30 | I21: RED PLANET.ISL | J21: 7549 | L21: 1 | M21: 0 | O21: =CONCATENATE(CI_!$R$1,C21,", '",D21,"', '",E21,"' , '",F21,"' , ",G21,",",H21,",'",I21,"',",J21,",'",K21,"',",L21,",",M21) -> EXECUTE [dbo].[PG_CI_USUARIO_PEARL] 139, 64, 'LEONORH', '12340' , 'LEONORH@PEARLLEATHER.COM.MX' , 2,30,'RED PLANET.ISL',7549,'',1,0
B22: 139 | C22: 66 | D22: KARENE | E22: 200816 | F22: RECIBO@PEARLLEATHER.COM.MX | G22: 3 | H22: 30 | I22: RED PLANET.ISL | J22: 10382 | L22: 1 | M22: 0 | O22: =CONCATENATE(CI_!$R$1,C22,", '",D22,"', '",E22,"' , '",F22,"' , ",G22,",",H22,",'",I22,"',",J22,",'",K22,"',",L22,",",M22) -> EXECUTE [dbo].[PG_CI_USUARIO_PEARL] 139, 66, 'KARENE', '200816' , 'RECIBO@PEARLLEATHER.COM.MX' , 3,30,'RED PLANET.ISL',10382,'',1,0
B23: 139 | C23: 67 | D23: GASPARH | E23: 12345 | F23: GASPARH@PEARLLEATHER.COM.MX | G23: 2 | H23: 30 | I23: THE BLUES.ISL | J23: 5628 | L23: 1 | M23: 0 | O23: =CONCATENATE(CI_!$R$1,C23,", '",D23,"', '",E23,"' , '",F23,"' , ",G23,",",H23,",'",I23,"',",J23,",'",K23,"',",L23,",",M23) -> EXECUTE [dbo].[PG_CI_USUARIO_PEARL] 139, 67, 'GASPARH', '12345' , 'GASPARH@PEARLLEATHER.COM.MX' , 2,30,'THE BLUES.ISL',5628,'',1,0
B24: 139 | C24: 68 | D24: ARMIDAH | E24: 2878 | F24: ARMIDAH@PEARLLEATHER.COM.MX | G24: 2 | H24: 30 | I24: FLAT NATURE.ISL | J24: 7041 | L24: 1 | M24: 0 | O24: =CONCATENATE(CI_!$R$1,C24,", '",D24,"', '",E24,"' , '",F24,"' , ",G24,",",H24,",'",I24,"',",J24,",'",K24,"',",L24,",",M24) -> EXECUTE [dbo].[PG_CI_USUARIO_PEARL] 139, 68, 'ARMIDAH', '2878' , 'ARMIDAH@PEARLLEATHER.COM.MX' , 2,30,'FLAT NATURE.ISL',7041,'',1,0
B25: 139 | C25: 69 | D25: MARIAS | E25: 12345 | F25: MARIAS@PEARLLEATHER.COM.MX | G25: 8 | H25: 30 | I25: FLAT NATURE.ISL | J25: 4158 | L25: 1 | M25: 0 | O25: =CONCATENATE(CI_!$R$1,C25,", '",D25,"', '",E25,"' , '",F25,"' , ",G25,",",H25,",'",I25,"',",J25,",'",K25,"',",L25,",",M25) -> EXECUTE [dbo].[PG_CI_USUARIO_PEARL] 139, 69, 'MARIAS', '12345' , 'MARIAS@PEARLLEATHER.COM.MX' , 8,30,'FLAT NATURE.ISL',4158,'',1,0
B26: 139 | C26: 70 | D26: FERNANDOG | E26: ferny | F26: FERNANDOG@PEARLLEATHER.COM.MX | G26: 3 | H26: 40 | I26: RED PLANET.ISL | J26: 8464 | L26: 1 | M26: 0 | O26: =CONCATENATE(CI_!$R$1,C26,", '",D26,"', '",E26,"' , '",F26,"' , ",G26,",",H26,",'",I26,"',",J26,",'",K26,"',",L26,",",M26) -> EXECUTE [dbo].[PG_CI_USUARIO_PEARL] 139, 70, 'FERNANDOG', 'ferny' , 'FERNANDOG@PEARLLEATHER.COM.MX' , 3,40,'RED PLANET.ISL',8464,'',1,0
B27: 139 | C27: 71 | D27: NAVIDR | E27: kgi01! | F27: NAVID@RACHMANTECH.COM | H27: 30 | I27: FLAT NATURE.ISL | J27: 0 | K27: magna | L27: 1 | M27: 1 | O27: =CONCATENATE(CI_!$R$1,C27,", '",D27,"', '",E27,"' , '",F27,"' , ",G27,",",H27,",'",I27,"',",J27,",'",K27,"',",L27,",",M27) -> EXECUTE [dbo].[PG_CI_USUARIO_PEARL] 139, 71, 'NAVIDR', 'kgi01!' , 'NAVID@RACHMANTECH.COM' , ,30,'FLAT NATURE.ISL',0,'magna',1,1
B28: 139 | C28: 72 | D28: ROXANAL | E28: 123789 | F28: @PEARLLEATHER.COM.MX | G28: 4 | H28: 40 | I28: THE BLUES.ISL | J28: 11879 | L28: 1 | M28: 0 | O28: =CONCATENATE(CI_!$R$1,C28,", '",D28,"', '",E28,"' , '",F28,"' , ",G28,",",H28,",'",I28,"',",J28,",'",K28,"',",L28,",",M28) -> EXECUTE [dbo].[PG_CI_USUARIO_PEARL] 139, 72, 'ROXANAL', '123789' , '@PEARLLEATHER.COM.MX' , 4,40,'THE BLUES.ISL',11879,'',1,0
B29: 139 | C29: 73 | D29: YAMILEXQ | E29: 1234 | F29: YAMILEXQ@PEARLLEATHER.COM.MX | H29: 30 | I29: FLAT NATURE.ISL | J29: 0 | K29: yamilex | L29: 1 | M29: 1 | O29: =CONCATENATE(CI_!$R$1,C29,", '",D29,"', '",E29,"' , '",F29,"' , ",G29,",",H29,",'",I29,"',",J29,",'",K29,"',",L29,",",M29) -> EXECUTE [dbo].[PG_CI_USUARIO_PEARL] 139, 73, 'YAMILEXQ', '1234' , 'YAMILEXQ@PEARLLEATHER.COM.MX' , ,30,'FLAT NATURE.ISL',0,'yamilex',1,1
B30: 139 | C30: 75 | D30: KARENA | E30: 102 | F30: KARENA@PEARLLEATHER.COM.MX | G30: 4 | H30: 30 | I30: NOIR MODERNE.ISL | J30: 12769 | L30: 1 | M30: 0 | O30: =CONCATENATE(CI_!$R$1,C30,", '",D30,"', '",E30,"' , '",F30,"' , ",G30,",",H30,",'",I30,"',",J30,",'",K30,"',",L30,",",M30) -> EXECUTE [dbo].[PG_CI_USUARIO_PEARL] 139, 75, 'KARENA', '102' , 'KARENA@PEARLLEATHER.COM.MX' , 4,30,'NOIR MODERNE.ISL',12769,'',1,0
B31: 139 | C31: 77 | D31: GENAROH | E31: 12345 | F31: EMBARQUES1@PEARLLEATHER.COM.MX | G31: 3 | H31: 30 | I31: FLAT NATURE.ISL | J31: 4880 | L31: 1 | M31: 0 | O31: =CONCATENATE(CI_!$R$1,C31,", '",D31,"', '",E31,"' , '",F31,"' , ",G31,",",H31,",'",I31,"',",J31,",'",K31,"',",L31,",",M31) -> EXECUTE [dbo].[PG_CI_USUARIO_PEARL] 139, 77, 'GENAROH', '12345' , 'EMBARQUES1@PEARLLEATHER.COM.MX' , 3,30,'FLAT NATURE.ISL',4880,'',1,0
B32: 139 | C32: 82 | D32: DANAC | E32: 2697 | F32: CERTI@PEARLLEATHER.COM.MX | G32: 4 | H32: 30 | I32: FLAT NATURE.ISL | J32: 10054 | L32: 1 | M32: 0 | O32: =CONCATENATE(CI_!$R$1,C32,", '",D32,"', '",E32,"' , '",F32,"' , ",G32,",",H32,",'",I32,"',",J32,",'",K32,"',",L32,",",M32) -> EXECUTE [dbo].[PG_CI_USUARIO_PEARL] 139, 82, 'DANAC', '2697' , 'CERTI@PEARLLEATHER.COM.MX' , 4,30,'FLAT NATURE.ISL',10054,'',1,0
B33: 139 | C33: 83 | D33: MARIANAC | E33: 1986 | F33: CERTI@PEARLLEATHER.COM.MX | H33: 30 | I33: RED PLANET.ISL | J33: 0 | K33: mariana castro | L33: 1 | M33: 1 | O33: =CONCATENATE(CI_!$R$1,C33,", '",D33,"', '",E33,"' , '",F33,"' , ",G33,",",H33,",'",I33,"',",J33,",'",K33,"',",L33,",",M33) -> EXECUTE [dbo].[PG_CI_USUARIO_PEARL] 139, 83, 'MARIANAC', '1986' , 'CERTI@PEARLLEATHER.COM.MX' , ,30,'RED PLANET.ISL',0,'mariana castro',1,1
B34: 139 | C34: 86 | D34: JORGEO | E34: calidad.30 | F34: JOLEGARIO@PEARLLEATHER.COM.MX | G34: 4 | H34: 30 | I34: FLAT NATURE.ISL | J34: 3589 | L34: 1 | M34: 0 | O34: =CONCATENATE(CI_!$R$1,C34,", '",D34,"', '",E34,"' , '",F34,"' , ",G34,",",H34,",'",I34,"',",J34,",'",K34,"',",L34,",",M34) -> EXECUTE [dbo].[PG_CI_USUARIO_PEARL] 139, 86, 'JORGEO', 'calidad.30' , 'JOLEGARIO@PEARLLEATHER.COM.MX' , 4,30,'FLAT NATURE.ISL',3589,'',1,0
B35: 139 | C35: 87 | D35: DIANAN | E35: Facturas1 | F35: RECIBO@PEARLLEATHER.COM.MX | G35: 3 | H35: 40 | I35: RED PLANET.ISL | J35: 10221 | L35: 1 | M35: 0 | O35: =CONCATENATE(CI_!$R$1,C35,", '",D35,"', '",E35,"' , '",F35,"' , ",G35,",",H35,",'",I35,"',",J35,",'",K35,"',",L35,",",M35) -> EXECUTE [dbo].[PG_CI_USUARIO_PEARL] 139, 87, 'DIANAN', 'Facturas1' , 'RECIBO@PEARLLEATHER.COM.MX' , 3,40,'RED PLANET.ISL',10221,'',1,0
B36: 139 | C36: 88 | D36: SISTEMAS | E36: m@ster++ | F36: SISTEMAS@PEARLLEATHER.COM.MX | H36: 30 | I36: RED PLANET.ISL | J36: 0 | K36: sistemas | L36: 1 | M36: 0 | O36: =CONCATENATE(CI_!$R$1,C36,", '",D36,"', '",E36,"' , '",F36,"' , ",G36,",",H36,",'",I36,"',",J36,",'",K36,"',",L36,",",M36) -> EXECUTE [dbo].[PG_CI_USUARIO_PEARL] 139, 88, 'SISTEMAS', 'm@ster++' , 'SISTEMAS@PEARLLEATHER.COM.MX' , ,30,'RED PLANET.ISL',0,'sistemas',1,0
B37: 139 | C37: 89 | D37: VIVIANAC | E37: 123450 | F37: VIVIANC@PEARLLEATHER.COM.MX | G37: 4 | H37: 30 | I37: FLAT NATURE.ISL | J37: 8242 | L37: 1 | M37: 0 | O37: =CONCATENATE(CI_!$R$1,C37,", '",D37,"', '",E37,"' , '",F37,"' , ",G37,",",H37,",'",I37,"',",J37,",'",K37,"',",L37,",",M37) -> EXECUTE [dbo].[PG_CI_USUARIO_PEARL] 139, 89, 'VIVIANAC', '123450' , 'VIVIANC@PEARLLEATHER.COM.MX' , 4,30,'FLAT NATURE.ISL',8242,'',1,0
B38: 139 | C38: 90 | D38: TANIAC | E38: 1726 | F38: RECIBO@PEARLLEATHER.COM.MX | G38: 3 | H38: 30 | I38: BLACK STYLE.ISL | J38: 10209 | L38: 1 | M38: 0 | O38: =CONCATENATE(CI_!$R$1,C38,", '",D38,"', '",E38,"' , '",F38,"' , ",G38,",",H38,",'",I38,"',",J38,",'",K38,"',",L38,",",M38) -> EXECUTE [dbo].[PG_CI_USUARIO_PEARL] 139, 90, 'TANIAC', '1726' , 'RECIBO@PEARLLEATHER.COM.MX' , 3,30,'BLACK STYLE.ISL',10209,'',1,0
B39: 139 | C39: 92 | D39: JOSES | E39: jose48320031 | F39: JOSES@PEARLLEATHER.COM.MX | G39: 2 | H39: 30 | I39: IG STYLE.ISL | J39: 13253 | L39: 1 | M39: 0 | O39: =CONCATENATE(CI_!$R$1,C39,", '",D39,"', '",E39,"' , '",F39,"' , ",G39,",",H39,",'",I39,"',",J39,",'",K39,"',",L39,",",M39) -> EXECUTE [dbo].[PG_CI_USUARIO_PEARL] 139, 92, 'JOSES', 'jose48320031' , 'JOSES@PEARLLEATHER.COM.MX' , 2,30,'IG STYLE.ISL',13253,'',1,0
B40: 139 | C40: 93 | D40: MARIAR | E40: 12345 | F40: MARIAR@PEARLLEATHER.COM.MX | H40: 30 | I40: NATILUS.ISL | J40: 0 | K40: maria romo | L40: 1 | M40: 1 | O40: =CONCATENATE(CI_!$R$1,C40,", '",D40,"', '",E40,"' , '",F40,"' , ",G40,",",H40,",'",I40,"',",J40,",'",K40,"',",L40,",",M40) -> EXECUTE [dbo].[PG_CI_USUARIO_PEARL] 139, 93, 'MARIAR', '12345' , 'MARIAR@PEARLLEATHER.COM.MX' , ,30,'NATILUS.ISL',0,'maria romo',1,1
...

Sheet usuarios totales
A1: K_USUARIO_PEARL | B1: D_USUARIO_PEARL | C1: PASSWORD_USUARIO_PEARL | D1: CORREO_USUARIO_PEARL | E1: USUARIO_TIPO | F1: TEMA_USUARIO_PEARL | G1: K_EMPLEADO_PEARL | H1: C_USUARIO_PEARL | I1: L_USUARIO_PEARL
A2: 41 | B2: RAFAELF | C2: killer | D2: RAFAELF@PEARLLEATHER.COM.MX | E2: A1 | F2: RED PLANET.ISL | G2: 6142 | I2: 1
A3: 42 | B3: OMARD | C3: 12340 | D3: OMARD@PEARLLEATHER.COM.MX | E3: Q1 | F3: RED PLANET.ISL | G3: 181 | I3: 1
A4: 43 | B4: JORGEH | C4: jorgeh | D4: JORGEH@PEARLLEATHER.COM.MX | E4: U2 | F4: FLAT NATURE.ISL | G4: 52 | I4: 1
A5: 44 | B5: GUILLERMOM | C5: nicole | D5: GUILLERMOM@PEARLLEATHER.COM.MX | E5: U1 | F5: FLAT NATURE.ISL | G5: 22 | I5: 1
A6: 45 | B6: PEDROV | C6: Saver10* | D6: PEDROV@PEARLLEATHER.COM.MX | E6: U1 | F6: RED PLANET.ISL | G6: 999 | I6: 1
A7: 47 | B7: MIGUELC | C7: Dalica9905 | D7: MIGUELC@PEARLLEATHER.COM.MX | E7: Q1 | F7: FLAT NATURE.ISL | G7: 1299 | I7: 1
A8: 48 | B8: IVAND | C8: 5623 | D8: IVAND@PEARLLEATHER.COM.MX | E8: U | F8: IG STYLE.ISL | G8: 2091 | I8: 1
A9: 49 | B9: OSCART | C9: 7890 | D9: OSCART@PEARLLEATHER.COM.MX | E9: U | F9: NATILUS.ISL | G9: 10901 | I9: 1
A10: 51 | B10: RECIBO1 | C10: 12345 | D10: PEDROA@PEARLLEATHER.COM.MX | E10: U | F10: IG STYLE.ISL | G10: 0 | I10: 1
A11: 52 | B11: RECIBO2 | C11: 12340 | D11: PEDROA@PEARLLEATHER.COM.MX | E11: U | F11: THE BLUES.ISL | G11: 0 | I11: 1
A12: 54 | B12: GILBERTOV | C12: Alexander1 | D12: GILBERTOV@PEARLLEATHER.COM.MX | E12: U1 | F12: RED PLANET.ISL | G12: 6898 | I12: 1
A13: 56 | B13: MANUELG | C13: Mangar83 | D13: MANUELG@PEARLLEATHER.COM.MX | E13: U2 | F13: FLAT NATURE.ISL | G13: 4475 | I13: 1
A14: 57 | B14: FABIOLAG | C14: fabiola | D14: FABIOLAG@PEARLLEATHER.COM.MX | E14: U | F14: FLAT NATURE.ISL | G14: 7658 | I14: 1
A15: 58 | B15: DIANAS | C15: 1604 | D15: @PEARLLEATHER.COM.MX | E15: U | F15: FLAT NATURE.ISL | G15: 10151 | I15: 1
A16: 59 | B16: ALEJANDROP | C16: alex | D16: EMBARQUES1@PEARLLEATHER.COM.MX | E16: U | F16: FLAT NATURE.ISL | G16: 6176 | I16: 1
A17: 60 | B17: ADRIANAD | C17: adriana | D17: ADRIANAD@PEARLLEATHER.COM.MX | E17: U | F17: FLAT NATURE.ISL | G17: 67 | I17: 1
A18: 62 | B18: PATRICIAC | C18: mebi1625 | D18: PATRICIAC@PEARLLEATHER.COM.MX | E18: U | F18: FLAT NATURE.ISL | G18: 7945 | I18: 1
A19: 63 | B19: LUISP | C19: luis | D19: LUISP@PEARLLEATHER.COM.MX | E19: U1 | F19: IG STYLE.ISL | G19: 0 | H19: luis perez | I19: 1
A20: 64 | B20: LEONORH | C20: 12340 | D20: LEONORH@PEARLLEATHER.COM.MX | E20: P1 | F20: RED PLANET.ISL | G20: 7549 | I20: 1
A21: 66 | B21: KARENE | C21: 200816 | D21: RECIBO@PEARLLEATHER.COM.MX | E21: U | F21: RED PLANET.ISL | G21: 10382 | I21: 1
A22: 67 | B22: GASPARH | C22: 12345 | D22: GASPARH@PEARLLEATHER.COM.MX | E22: P1 | F22: THE BLUES.ISL | G22: 5628 | I22: 1
A23: 68 | B23: ARMIDAH | C23: 2878 | D23: ARMIDAH@PEARLLEATHER.COM.MX | E23: P1 | F23: FLAT NATURE.ISL | G23: 7041 | I23: 1
A24: 69 | B24: MARIAS | C24: 12345 | D24: MARIAS@PEARLLEATHER.COM.MX | E24: U | F24: FLAT NATURE.ISL | G24: 4158 | I24: 1
A25: 70 | B25: FERNANDOG | C25: ferny | D25: FERNANDOG@PEARLLEATHER.COM.MX | E25: U1 | F25: RED PLANET.ISL | G25: 8464 | I25: 1
A26: 71 | B26: NAVIDR | C26: kgi01! | D26: NAVID@RACHMANTECH.COM | E26: U | F26: FLAT NATURE.ISL | G26: 0 | I26: 1
A27: 72 | B27: ROXANAL | C27: 123789 | D27: @PEARLLEATHER.COM.MX | E27: U1 | F27: THE BLUES.ISL | G27: 11879 | I27: 1
A28: 73 | B28: YAMILEXQ | C28: 1234 | D28: YAMILEXQ@PEARLLEATHER.COM.MX | E28: P1 | F28: FLAT NATURE.ISL | G28: 0 | I28: 1
A29: 75 | B29: KARENA | C29: 102 | D29: KARENA@PEARLLEATHER.COM.MX | E29: U | F29: NOIR MODERNE.ISL | G29: 12769 | I29: 1
A30: 77 | B30: GENAROH | C30: 12345 | D30: EMBARQUES1@PEARLLEATHER.COM.MX | E30: U | F30: FLAT NATURE.ISL | G30: 4880 | I30: 1
A31: 82 | B31: DANAC | C31: 2697 | D31: CERTI@PEARLLEATHER.COM.MX | E31: U | F31: FLAT NATURE.ISL | G31: 10054 | I31: 1
A32: 83 | B32: MARIANAC | C32: 1986 | D32: CERTI@PEARLLEATHER.COM.MX | E32: U | F32: RED PLANET.ISL | G32: 0 | H32: mariana castro | I32: 1
A33: 86 | B33: JORGEO | C33: calidad.30 | D33: JOLEGARIO@PEARLLEATHER.COM.MX | E33: U | F33: FLAT NATURE.ISL | G33: 3589 | I33: 1
A34: 87 | B34: DIANAN | C34: Facturas1 | D34: RECIBO@PEARLLEATHER.COM.MX | E34: U1 | F34: RED PLANET.ISL | G34: 10221 | I34: 1
A35: 88 | B35: SISTEMAS | C35: m@ster++ | D35: SISTEMAS@PEARLLEATHER.COM.MX | E35: A1 | F35: RED PLANET.ISL | G35: 0 | I35: 1
A36: 89 | B36: VIVIANAC | C36: 123450 | D36: VIVIANC@PEARLLEATHER.COM.MX | E36: Q1 | F36: FLAT NATURE.ISL | G36: 8242 | I36: 1
A37: 90 | B37: TANIAC | C37: 1726 | D37: RECIBO@PEARLLEATHER.COM.MX | E37: U | F37: BLACK STYLE.ISL | G37: 10209 | I37: 1
A38: 92 | B38: JOSES | C38: jose48320031 | D38: JOSES@PEARLLEATHER.COM.MX | E38: U | F38: IG STYLE.ISL | G38: 13253 | I38: 1
A39: 93 | B39: MARIAR | C39: 12345 | D39: MARIAR@PEARLLEATHER.COM.MX | E39: P1 | F39: NATILUS.ISL | G39: 0 | H39: maria romo | I39: 1
A40: 94 | B40: FRANCISCOM | C40: cuarris987 | D40: @PEARLLEATHER.COM.MX | E40: U | F40: IG STYLE.ISL | G40: 13189 | I40: 1
...

Sheet Sheet1
A1: K_USUARIO_PEARL | B1: D_USUARIO_PEARL | C1: PASSWORD_USUARIO_PEARL | D1: CORREO_USUARIO_PEARL | E1: USUARIO_TIPO | F1: TEMA_USUARIO_PEARL | G1: K_EMPLEADO_PEARL | H1: C_USUARIO_PEARL | I1: L_USUARIO_PEARL
A2: 41 | B2: RAFAELF | C2: killer | D2: RAFAELF@PEARLLEATHER.COM.MX | E2: A1 | F2: RED PLANET.ISL | G2: 6142 | I2: 1
A3: 42 | B3: OMARD | C3: 12340 | D3: OMARD@PEARLLEATHER.COM.MX | E3: Q1 | F3: RED PLANET.ISL | G3: 181 | I3: 1
A4: 43 | B4: JORGEH | C4: jorgeh | D4: JORGEH@PEARLLEATHER.COM.MX | E4: U2 | F4: FLAT NATURE.ISL | G4: 52 | I4: 1
A5: 44 | B5: GUILLERMOM | C5: nicole | D5: GUILLERMOM@PEARLLEATHER.COM.MX | E5: U1 | F5: FLAT NATURE.ISL | G5: 22 | I5: 1
A6: 45 | B6: PEDROV | C6: Saver10* | D6: PEDROV@PEARLLEATHER.COM.MX | E6: U1 | F6: RED PLANET.ISL | G6: 999 | I6: 1
A7: 47 | B7: MIGUELC | C7: Dalica9905 | D7: MIGUELC@PEARLLEATHER.COM.MX | E7: Q1 | F7: FLAT NATURE.ISL | G7: 1299 | I7: 1
A8: 48 | B8: IVAND | C8: 5623 | D8: IVAND@PEARLLEATHER.COM.MX | E8: U | F8: IG STYLE.ISL | G8: 2091 | I8: 1
A9: 49 | B9: OSCART | C9: 7890 | D9: OSCART@PEARLLEATHER.COM.MX | E9: U | F9: NATILUS.ISL | G9: 10901 | I9: 1
A10: 51 | B10: RECIBO1 | C10: 12345 | D10: PEDROA@PEARLLEATHER.COM.MX | E10: U | F10: IG STYLE.ISL | G10: 0 | I10: 1
A11: 52 | B11: RECIBO2 | C11: 12340 | D11: PEDROA@PEARLLEATHER.COM.MX | E11: U | F11: THE BLUES.ISL | G11: 0 | I11: 1
A12: 54 | B12: GILBERTOV | C12: Alexander1 | D12: GILBERTOV@PEARLLEATHER.COM.MX | E12: U1 | F12: RED PLANET.ISL | G12: 6898 | I12: 1
A13: 56 | B13: MANUELG | C13: Mangar83 | D13: MANUELG@PEARLLEATHER.COM.MX | E13: U2 | F13: FLAT NATURE.ISL | G13: 4475 | I13: 1
A14: 57 | B14: FABIOLAG | C14: fabiola | D14: FABIOLAG@PEARLLEATHER.COM.MX | E14: U | F14: FLAT NATURE.ISL | G14: 7658 | I14: 1
A15: 58 | B15: DIANAS | C15: 1604 | D15: @PEARLLEATHER.COM.MX | E15: U | F15: FLAT NATURE.ISL | G15: 10151 | I15: 1
A16: 59 | B16: ALEJANDROP | C16: alex | D16: EMBARQUES1@PEARLLEATHER.COM.MX | E16: U | F16: FLAT NATURE.ISL | G16: 6176 | I16: 1
A17: 60 | B17: ADRIANAD | C17: adriana | D17: ADRIANAD@PEARLLEATHER.COM.MX | E17: U | F17: FLAT NATURE.ISL | G17: 67 | I17: 1
A18: 62 | B18: PATRICIAC | C18: mebi1625 | D18: PATRICIAC@PEARLLEATHER.COM.MX | E18: U | F18: FLAT NATURE.ISL | G18: 7945 | I18: 1
A19: 63 | B19: LUISP | C19: luis | D19: LUISP@PEARLLEATHER.COM.MX | E19: U1 | F19: IG STYLE.ISL | G19: 0 | H19: luis perez | I19: 1
A20: 64 | B20: LEONORH | C20: 12340 | D20: LEONORH@PEARLLEATHER.COM.MX | E20: P1 | F20: RED PLANET.ISL | G20: 7549 | I20: 1
A21: 66 | B21: KARENE | C21: 200816 | D21: RECIBO@PEARLLEATHER.COM.MX | E21: U | F21: RED PLANET.ISL | G21: 10382 | I21: 1
A22: 67 | B22: GASPARH | C22: 12345 | D22: GASPARH@PEARLLEATHER.COM.MX | E22: P1 | F22: THE BLUES.ISL | G22: 5628 | I22: 1
A23: 68 | B23: ARMIDAH | C23: 2878 | D23: ARMIDAH@PEARLLEATHER.COM.MX | E23: P1 | F23: FLAT NATURE.ISL | G23: 7041 | I23: 1
A24: 69 | B24: MARIAS | C24: 12345 | D24: MARIAS@PEARLLEATHER.COM.MX | E24: U | F24: FLAT NATURE.ISL | G24: 4158 | I24: 1
A25: 70 | B25: FERNANDOG | C25: ferny | D25: FERNANDOG@PEARLLEATHER.COM.MX | E25: U1 | F25: RED PLANET.ISL | G25: 8464 | I25: 1
A26: 71 | B26: NAVIDR | C26: kgi01! | D26: NAVID@RACHMANTECH.COM | E26: U | F26: FLAT NATURE.ISL | G26: 0 | H26: navid rachman() | I26: 1
A27: 72 | B27: ROXANAL | C27: 123789 | D27: @PEARLLEATHER.COM.MX | E27: U1 | F27: THE BLUES.ISL | G27: 11879 | I27: 1
A28: 73 | B28: YAMILEXQ | C28: 1234 | D28: YAMILEXQ@PEARLLEATHER.COM.MX | E28: P1 | F28: FLAT NATURE.ISL | G28: 0 | H28: yamilex quezada | I28: 1
A29: 75 | B29: KARENA | C29: 102 | D29: KARENA@PEARLLEATHER.COM.MX | E29: U | F29: NOIR MODERNE.ISL | G29: 12769 | I29: 1
A30: 77 | B30: GENAROH | C30: 12345 | D30: EMBARQUES1@PEARLLEATHER.COM.MX | E30: U | F30: FLAT NATURE.ISL | G30: 4880 | I30: 1
A31: 82 | B31: DANAC | C31: 2697 | D31: CERTI@PEARLLEATHER.COM.MX | E31: U | F31: FLAT NATURE.ISL | G31: 10054 | I31: 1
A32: 83 | B32: MARIANAC | C32: 1986 | D32: CERTI@PEARLLEATHER.COM.MX | E32: U | F32: RED PLANET.ISL | G32: 0 | H32: mariana castro | I32: 1
A33: 86 | B33: JORGEO | C33: calidad.30 | D33: JOLEGARIO@PEARLLEATHER.COM.MX | E33: U | F33: FLAT NATURE.ISL | G33: 3589 | I33: 1
A34: 87 | B34: DIANAN | C34: Facturas1 | D34: RECIBO@PEARLLEATHER.COM.MX | E34: U1 | F34: RED PLANET.ISL | G34: 10221 | I34: 1
A35: 88 | B35: SISTEMAS | C35: m@ster++ | D35: SISTEMAS@PEARLLEATHER.COM.MX | E35: A1 | F35: RED PLANET.ISL | G35: 0 | I35: 1
A36: 89 | B36: VIVIANAC | C36: 123450 | D36: VIVIANC@PEARLLEATHER.COM.MX | E36: Q1 | F36: FLAT NATURE.ISL | G36: 8242 | I36: 1
A37: 90 | B37: TANIAC | C37: 1726 | D37: RECIBO@PEARLLEATHER.COM.MX | E37: U | F37: BLACK STYLE.ISL | G37: 10209 | I37: 1
A38: 92 | B38: JOSES | C38: jose48320031 | D38: JOSES@PEARLLEATHER.COM.MX | E38: U | F38: IG STYLE.ISL | G38: 13253 | I38: 1
A39: 93 | B39: MARIAR | C39: 12345 | D39: MARIAR@PEARLLEATHER.COM.MX | E39: P1 | F39: NATILUS.ISL | G39: 0 | H39: maria romo | I39: 1
A40: 94 | B40: FRANCISCOM | C40: cuarris987 | D40: @PEARLLEATHER.COM.MX | E40: U | F40: IG STYLE.ISL | G40: 13189 | I40: 1
...

Sheet usuario_para_baja
A1: K_USUARIO_PEARL | B1: D_USUARIO_PEARL | C1: CORREO_USUARIO_PEARL | D1: K_EMPLEADO_PEARL | E1: C_USUARIO_PEARL
A2: 51 | B2: RECIBO1 | C2: PEDROA@PEARLLEATHER.COM.MX
A3: 52 | B3: RECIBO2 | C3: PEDROA@PEARLLEATHER.COM.MX
A4: 63 | B4: LUISP | C4: LUISP@PEARLLEATHER.COM.MX | D4: 0 | E4: LUIS PEREZ
A5: 71 | B5: NAVIDR | C5: NAVID@RACHMANTECH.COM | E5: NAVID RACHMAN()
A6: 73 | B6: YAMILEXQ | C6: YAMILEXQ@PEARLLEATHER.COM.MX | D6: 0 | E6: YAMILEX QUEZADA
A7: 83 | B7: MARIANAC | C7: CERTI@PEARLLEATHER.COM.MX | D7: 0 | E7: MARIANA CASTRO
A8: 88 | B8: SISTEMAS | C8: SISTEMAS@PEARLLEATHER.COM.MX
A9: 93 | B9: MARIAR | C9: MARIAR@PEARLLEATHER.COM.MX | D9: 0 | E9: MARIA ROMO
A10: 97 | B10: ELENAR | C10: ELENAR@PEARLLEATHER.COM.MX | D10: 0 | E10: ELENA RODRIGUEZ
A11: 101 | B11: LEYVERR | C11: @PEARLLEATHER.COM.MX | D11: 0 | E11: LEYVER ROBLERO
A12: 103 | B12: SUPERVISOR | C12: XX@PEARLLEATHER.COM.MX
A13: 110 | B13: FRAYJ | C13: FRAYJ@PEARLLEATHER.COM.MX | D13: 0 | E13: FRAY JIMENEZ
A14: 112 | B14: ALMAZ | C14: @PEARLLEATHER.COM.MX | D14: 0 | E14: ALMA ZUNIGA
A15: 113 | B15: ERNESTOG | C15: ERNESTOG@PEARLLEATHER.COM.MX | D15: 0 | E15: ERNESTO GAYTAN
A16: 114 | B16: JOSUEC | C16: JOSUEC@PEARLLEATHER.COM.MX | D16: 0 | E16: JOSUE CHAVEZ
A17: 122 | B17: JESUSR | C17: JESUSR@PEARLLEATHER.COM.MX | D17: 0 | E17: JESUS ROJERO
A18: 126 | B18: ANAHIG | C18: @PEARLLEATHER.COM.MX | D18: 0 | E18: ANAHI GALLEGOS
